Workbook

Sheet DB_(0527)
B1: 출처
A2: 원천데이터 | B2: 고시문
A3: 원천데이터 | B3: KB시세
A4: 계산데이터
A5: 전문가판단 | B5: 경험치
A6: 전문가판단 | B6: 2차계산
A7: 사용자표시 | AH7: 시뮬레이터 | AI7: 시뮬레이터
H9: 계산결과와 고시문자료 크로스체크 필요 | J9: 시뮬레이터 | L9: 시뮬레이터 | P9: 계산결과와 고시문자료 크로스체크 필요 | T9: 시뮬레이터 | AA9: 종전 타입별로 바뀌는 항목 | AB9: 종전 타입별로 바뀌는 항목 | AC9: 종전 타입별로 바뀌는 항목 | AD9: 종전 타입별로 바뀌는 항목 | AE9: 종전 타입별로 바뀌는 항목 | AH9: 계산결과와 고시문자료 크로스체크 필요 | AJ9: 계산결과와 고시문자료 크로스체크 필요 | AT9: 시뮬레이터 | DG9: 종전 타입별로 바뀌는 항목 | DH9: 종전 타입별로 바뀌는 항목 | DI9: 종전 타입별로 바뀌는 항목 | DJ9: 종전 타입별로 바뀌는 항목 | DK9: 종전 타입별로 바뀌는 항목
BO10: *) 압구정3구역은, 종후 평단가가 나와있지만, 종후 면적이 자세히 나와있지 않아서, 여기서 분양평형(3)을 이끌어내는 것이 또한 포커스다
A11: 압구정3page | J11: 11 | L11: 11 | N11: 11 | V11: 10 | W11: 11 | Z11: 11 | AA11: 11 | AB11: 11 | AC11: 11 | AH11: 12 | BF11: 10 | BO11: 11 | BQ11: 22 | BR11: 22 | BV11: 22 | BZ11: 22 | CE11: 22 | CG11: 22 | CH11: 22 | CI11: 22 | CJ11: 22 | CK11: 22 | CN11: 10 | CO11: 11 | CR11: =+J11 -> 11 | CS11: =+L11 -> 11 | DF11: 11 | DG11: 11 | DH11: 11 | DI11: 11
A12: 신반포2page | M12: 10 | N12: 10 | V12: 9 | W12: 9 | BF12: 10 | BG12: 10 | BH12: 10 | BI12: 10 | BJ12: 10 | DP12: *) 여긴 종후 면적과 종후 가액 합계가 나와 있어서 평균적인 종후 자산 평단가 뽑아내는게 포커스
A13: 목동6page
A14: 여의도시범page | AT14: 슬라이더 | BO14: 16 | BQ14: 25 | CE14: 25 | CG14: 25 | CI14: 25 | CK14: 25 | CN14: 26
A15: 은마page | H15: 18 | BO15: 18 | CE15: 18 | CN15: 3
A16: 명칭 | B16: 주소 | C16: 고시문 날짜 | D16: 고시명 | E16: 연면적합계m2 | F16: 연면적 출처 | H16: 종후자산합계(계산결과) | I16: 일반분양총액 | J16: 일분 분양평단가 | K16: 조합분양총액 | L16: 조분 분양평단가 | M16: 임대수입 | N16: 주택 외 | P16: 사업비합계 (계산결과) | Q16: 공사비(계산결과) | R16: 기타사업비(계산결과) | S16: 공사비 대비 기타사업비 비율 | T16: 평당공사비 | V16: 종전합계 | W16: 종전자산(주택)합계 | X16: 기타종전자산 (계산결과) | Z16: 종전타입수 | AA16: 종전-단지명 | AB16: 종전-타입명 | AC16: 종전-세대단가 | AD16: KB시세 | AE16: 적용KB분양면적 | AF16: KB시점 | AH16: 전용84 조합원분양가 | AI16: 전용84 일반분양 | AJ16: 비례율(계산결과) | AL16: 유사단지선정 | AM16: 유사단지 주소 | AN16: 유사단지 전용84KB시세(상한) | AO16: KB시점 | AP16: 유사단지 분양면적 | AQ16: 유사단지평단가 | AR16: 본건84분양면적 | AS16: 배율 | AT16: 본건전용84신축가격(추정) | AU16: 총투자금 | AV16: 마진 | AX16: 시뮬레이션결과 | AZ16: 종전 타입별 분담금 | BB16: 수익률 | BD16: 모든 단지 로직 | BF16: 사업비합계 | BG16: 공사비(계산결과) | BH16: 기타사업비(계산결과) | BI16: 공사비 대비 기타사업비 비율 | BJ16: 평당공사비 | BM16: 압구정3특별로직 | BO16: 종전세대수 | BP16: 일분세대수(계산) | BQ16: (일분+조분)분양세대수 | BR16: 분양1세대수 | BS16: 분양1면적 | BT16: 분양1조분세대수 | BU16: 분양1일분세대수 | BV16: 분양2세대수 | BW16: 분양2면적 | BX16: 분양1조분세대수 | BY16: 분양1일분세대수 | BZ16: 분양3세대수 | CA16: 분양3면적 | CB16: 분양1조분세대수 | CC16: 분양1일분세대수 | CE16: 임대세대수(법적상한) | CF16: 임대세대수(기부채납) | CG16: 임대1세대수 | CH16: 임대1면적 | CI16: 임대2세대수 | CJ16: 임대2면적 | CK16: 총세대수 | CM16: 임대단가 | CN16: 종후자산합계 | CO16: 주택 외 | CP16: 임대분양가 | CQ16: 주택분양가 | CR16: =+J16 -> 일분 분양평단가 | CS16: =+L16 -> 조분 분양평단가 | CT16: 59조분+일분 | CU16: 84조분+일분 | CV16: 분양3 분양가 | CW16: 분양3 면적 추정 | CY16: 일반분양면적 | CZ16: =+I16 -> 일반분양총액 | DA16: 조합원분양 면적 | DB16: =+K16 -> 조합분양총액 | DD16: 압구정3특별로직 | DF16: 종전타입수 | DG16: 종전-단지명 | DH16: 종전-타입명 | DI16: 종전-세대단가 | DJ16: KB 시세 없는 자료 추정 | DK16: 적용KB분양면적 | DL16: KB시점
A17: 명칭 | B17: 주소 | C17: 고시문 날짜 | D17: 고시명 | E17: 연면적합계m2 | F17: 연면적 출처 | H17: 종후자산합계(계산결과) | I17: 일반분양총액 | J17: 일분 분양평단가 | K17: 조합분양총액 | L17: 조분 분양평단가 | M17: 임대수입 | N17: 주택 외 | P17: 사업비합계 (계산결과) | Q17: 공사비(계산결과) | R17: 기타사업비(계산결과) | S17: 공사비 대비 기타사업비 비율 | T17: 평당공사비 | V17: 종전합계 | W17: 종전자산(주택)합계 | X17: 기타종전자산 (계산결과) | Z17: 종전타입수 | AA17: 종전-단지명 | AB17: 종전-타입명 | AC17: 종전-세대단가 | AD17: KB시세 | AE17: 적용KB분양면적 | AF17: KB시점 | AH17: 전용84 조합원분양가 | AI17: 전용84 일반분양 | AJ17: 비례율(계산결과) | AL17: 유사단지선정 | AM17: 유사단지 주소 | AN17: 유사단지 전용84KB시세(상한) | AO17: KB시점 | AP17: 유사단지 분양면적 | AQ17: 유사단지평단가 | AR17: 본건84분양면적 | AS17: 배율 | AT17: 본건전용84신축가격(추정) | AU17: 총투자금 | AV17: 마진 | BF17: 사업비합계 | BG17: 공사비 | BH17: 기타사업비 | BI17: 공사비 대비 기타사업비 비율 | BJ17: 평당공사비 | DN17: 신반포3 특별로직 | DP17: 조합원분양가총액 | EI17: 조합원분양면적총액 | EJ17: 평균 조합원분양 단가 | EK17: 일반분양가총액 | FD17: 일반분양면적총액 | FE17: 평균 일반분양단가
A18: 명칭 | B18: 주소 | C18: 고시문 날짜 | D18: 고시명 | E18: 연면적합계m2 | F18: 연면적 출처 | H18: 종후자산합계(계산결과) | I18: 일반분양총액 | J18: 일분 분양평단가 | K18: 조합분양총액 | L18: 조분 분양평단가 | M18: 임대수입 | N18: 주택 외(VAT/대여금이자포함) | P18: 사업비합계 (계산결과) | Q18: 공사비(계산결과) | R18: 기타사업비(계산결과) | S18: 공사비 대비 기타사업비 비율 | T18: 평당공사비 | V18: 종전합계 | W18: 종전자산(주택)합계 | X18: 기타종전자산 (계산결과) | Z18: 종전타입수 | AA18: 종전-단지명 | AB18: 종전-타입명 | AC18: 종전-세대단가 | AD18: KB시세 | AE18: 적용KB분양면적 | AF18: KB시점 | AH18: 전용84 조합원분양가 | AI18: 전용84 일반분양 | AJ18: 비례율(계산결과) | AL18: 유사단지선정 | AM18: 유사단지 주소 | AN18: 유사단지 전용84KB시세(상한) | AO18: KB시점 | AP18: 유사단지 분양면적 | AQ18: 유사단지평단가 | AR18: 본건84분양면적 | AS18: 배율 | AT18: 본건전용84신축가격(추정) | AU18: 총투자금 | AV18: 마진 | BF18: 사업비합계 | BG18: 공사비 | BH18: 기타사업비 | BI18: 공사비 대비 기타사업비 비율 | BJ18: 평당공사비 | DN18: 목동6 동일 로직 | DP18: 조합원분양가총액 | EI18: 조합원분양면적총액 | EJ18: 평균 조합원분양 단가 | EK18: 일반분양가총액 | FD18: 일반분양면적총액 | FE18: 평균 일반분양단가
A19: 명칭 | B19: 주소 | C19: 고시문 날짜 | D19: 고시명 | E19: 연면적합계m2 | F19: 연면적 출처 | H19: 종후자산합계(계산결과) | I19: 일반분양총액 | J19: 일분 분양평단가 | K19: 조합분양총액 | L19: 조분 분양평단가(계산) | M19: 임대수입 | N19: 주택 외 | P19: 사업비합계 (계산결과) | Q19: 공사비(계산결과) | R19: 기타사업비(계산결과) | S19: 공사비 대비 기타사업비 비율 | T19: 평당공사비 | V19: 종전합계 | W19: 종전자산(주택)합계 | X19: 기타종전자산 (계산결과) | Z19: 종전타입수 | AA19: 종전-단지명 | AB19: 종전-타입명 | AC19: 종전-세대단가 | AD19: KB시세 | AE19: 적용KB분양면적 | AF19: KB시점 | AH19: 전용84 조합원분양가 | AI19: 전용84 일반분양 | AJ19: 비례율(계산결과) | AL19: 유사단지선정 | AM19: 유사단지 주소 | AN19: 유사단지 전용84KB시세(상한) | AO19: KB시점 | AP19: 유사단지 분양면적 | AQ19: 유사단지평단가 | AR19: 본건84분양면적 | AS19: 배율 | AT19: 본건전용84신축가격(추정) | AU19: 총투자금 | AV19: 마진 | BF19: 사업비합계 | BG19: 공사비(계산결과) | BH19: 기타사업비(계산결과) | BI19: 공사비 대비 기타사업비 비율 | BJ19: 평당공사비 | BM19: 여의도시범 로직 | BO19: 종전세대수 | BP19: 일분세대수(계산) | BQ19: (일분+조분)분양세대수 | BR19: 분양1세대수 | BS19: 분양1면적 | BT19: 분양1조분세대수 | BU19: 분양1일분세대수 | BV19: 분양2세대수 | BW19: 분양2면적 | BX19: 분양1조분세대수 | BY19: 분양1일분세대수 | BZ19: 분양3세대수 | CA19: 분양3면적 | CB19: 분양1조분세대수 | CC19: 분양1일분세대수 | CE19: 임대세대수(법적상한) | CF19: 임대세대수(기부채납) | CG19: 임대1세대수 | CH19: 임대1면적 | CI19: 임대2세대수 | CJ19: 임대2면적 | CK19: 총세대수 | CM19: 임대단가 | CN19: 종후자산합계 | CO19: 주택 외 | CP19: 임대분양가 | CQ19: 주택분양가 | CR19: =+J19 -> 일분 분양평단가 | CS19: =+L19 -> 조분 분양평단가(계산) | CT19: 59조분+일분 | CU19: 84조분+일분 | CV19: 분양3 분양가 | CW19: 분양3 면적 추정 | CY19: 일반분양면적 | CZ19: =+I19 -> 일반분양총액 | DA19: 조합원분양 면적 | DB19: =+K19 -> 조합분양총액 | DN19: 목동6 동일 로직 | DP19: 조합원분양가총액 | EI19: 조합원분양면적총액 | EJ19: 평균 조합원분양 단가 | EK19: 일반분양가총액 | FD19: 일반분양면적총액 | FE19: 평균 일반분양단가
A20: 명칭 | B20: 주소 | C20: 고시문 날짜 | D20: 고시명 | E20: 연면적합계m2 | F20: 연면적 출처 | H20: 종후자산합계(계산결과) | I20: 일반분양총액 | J20: 일분 분양평단가 | K20: 조합분양총액 | L20: 조분 분양평단가(계산) | M20: 임대수입 | N20: 주택 외 | P20: 사업비합계 (계산결과) | Q20: 공사비(계산결과) | R20: 기타사업비(계산결과) | S20: 공사비 대비 기타사업비 비율 | T20: 평당공사비 | V20: 종전합계 | W20: 종전자산(주택)합계 | X20: 기타종전자산 (계산결과) | Z20: 종전타입수 | AA20: 종전-단지명 | AB20: 종전-타입명 | AC20: 종전-세대단가 | AD20: KB시세 | AE20: 적용KB분양면적 | AF20: KB시점 | AH20: 전용84 조합원분양가 | AI20: 전용84 일반분양 | AJ20: 비례율(계산결과) | AL20: 유사단지선정 | AM20: 유사단지 주소 | AN20: 유사단지 전용84 부동산뱅크시세(상한) | AO20: KB시점 | AP20: 유사단지 분양면적 | AQ20: 유사단지평단가 | AR20: 본건84분양면적 | AS20: 배율 | AT20: 본건전용84신축가격(추정) | AU20: 총투자금 | AV20: 마진 | AX20: 시뮬레이션결과 | AZ20: 종전 타입별 분담금 | BB20: 수익률 | BD20: 모든 단지 로직 | BF20: 사업비합계 | BG20: 공사비(계산결과) | BH20: 기타사업비(계산결과) | BI20: 공사비 대비 기타사업비 비율 | BJ20: 평당공사비 | BM20: 압구정3특별로직 | BO20: 종전세대수 | BP20: 일분세대수(계산) | BQ20: (일분+조분)분양세대수 | BR20: 분양1세대수 | BS20: 분양1면적 | BT20: 분양1조분세대수 | BU20: 분양1일분세대수 | BV20: 분양2세대수 | BW20: 분양2면적 | BX20: 분양1조분세대수 | BY20: 분양1일분세대수 | BZ20: 분양3세대수 | CA20: 분양3면적 | CB20: 분양1조분세대수 | CC20: 분양1일분세대수 | CE20: 임대세대수(법적상한) | CF20: 임대세대수(기부채납) | CG20: 임대1세대수 | CH20: 임대1면적 | CI20: 임대2세대수 | CJ20: 임대2면적 | CK20: 총세대수 | CM20: 임대단가 | CN20: 종후자산합계 | CO20: 주택 외 | CP20: 임대분양가 | CQ20: 주택분양가 | CR20: =+J20 -> 일분 분양평단가 | CS20: =+L20 -> 조분 분양평단가(계산) | CT20: 59조분+일분 | CU20: 84조분+일분 | CV20: 분양3 분양가 | CW20: 분양3 면적 추정 | CY20: 일반분양면적 | CZ20: =+I20 -> 일반분양총액 | DA20: 조합원분양 면적 | DB20: =+K20 -> 조합분양총액 | DD20: 압구정3특별로직 | DF20: 종전타입수 | DG20: 종전-단지명 | DH20: 종전-타입명 | DI20: 종전-세대단가 | DJ20: KB 시세 없는 자료 추정 | DK20: 적용KB분양면적 | DL20: KB시점
A21: 압구정3구역 | B21: 서울특별시 강남구 압구정동 369-1 | C21: 45992 | D21: 서울특별시 강남구공고 제 2025-2711호 | E21: 1414453 | F21: 구글링 | H21: =+I21+K21+M21+N21 -> 21108000 | I21: =+J21*CY21*0.3025 -> 2658697.2 | J21: 85 | K21: =+L21*DA21*0.3025 -> 17015568 | L21: 83 | M21: =+CP21 -> 101095.5 | N21: 1332639 | P21: =+Q21+R21 -> 5887500 | Q21: =+T21*E21*0.3025 -> 4528846.2 | R21: =+Q21*S21 -> 1358653.8 | S21: =+BI21 -> 0.3 | T21: =+BJ21 -> 10.584581 | V21: 24930400 | W21: 23069157 | X21: =+V21-W21 -> 1861243 | Z21: 1 | AA21: 1,2차 | AB21: 43 | AC21: 5063 | AD21: 6700 | AE21: 141 | AF21: 46160 | AH21: =+AR21*L21*0.3025 -> 2862.255 | AI21: =+J21*AR21*0.3025 -> 2931.225 | AJ21: =+(H21-P21)/V21 -> 0.61051969 | AL21: 래미안원베일리 | AM21: 서울시 서초구 반포동 1 | AN21: 6700 | AO21: =+AF21 -> 46160 | AP21: 111.79 | AQ21: =+AN21/(AP21*0.3025) -> 198.12828 | AR21: 114 | AS21: 0.2 | AT21: =+AQ21*AR21*(1+AS21)*0.3025 -> 8198.9444 | AU21: =+AD21+AZ21 -> 6471.1938 | AV21: =+AT21-AU21 -> 1727.7506 | AZ21: =+AH21-(AC21*AJ21) -> -228.80617 | BB21: =+AV21/AU21 -> 0.26699102 | BD21: 공사비 뽑아내기 | BF21: 5887500 | BG21: =+BF21/(1+BI21) -> 4528846.2 | BH21: =+BF21-BG21 -> 1358653.8 | BI21: 0.3 | BJ21: =+BG21/(E21*0.3025) -> 10.584581 | BO21: 3934 | BP21: =+BQ21-BO21 -> 600 | BQ21: 4534 | BR21: 522 | BS21: 80 | BT21: =+ROUND(BR21*BO21/BQ21,0) -> 453 | BU21: =+BR21-BT21 -> 69 | BV21: 486 | BW21: 114 | BX21: =+ROUND(BV21*BO21/BQ21,0) -> 422 | BY21: =+BV21-BX21 -> 64 | BZ21: 3526 | CA21: =+CW21 -> 193.97208 | CB21: =+ROUND(BZ21*BO21/BQ21,0) -> 3059 | CC21: =+BZ21-CB21 -> 467 | CE21: 641 | CG21: 511 | CH21: =+BS21 -> 80 | CI21: 130 | CJ21: =+BW21 -> 114 | CK21: =+BQ21+CE21+CF21 -> 5175 | CM21: 6 | CN21: 21108000 | CO21: =+N21 -> 1332639 | CP21: =+CM21*(CG21*CH21+CI21*CJ21)*0.3025 -> 101095.5 | CQ21: =+CN21-CO21-CP21 -> 19674266 | CR21: =+J21 -> 85 | CS21: =+L21 -> 83 | CT21: =+(CR21*BS21*BU21+CS21*BS21*BT21)*0.3025 -> 1051828.8 | CU21: =+(CR21*BW21*BY21+CS21*BW21*BX21)*0.3025 -> 1395470 | CV21: =+CQ21-CT21-CU21 -> 17226967 | CW21: =+CV21/(CR21*CC21*0.3025+CS21*CB21*0.3025) -> 193.97208 | CY21: =+(BS21*BU21+BW21*BY21+CA21*CC21) -> 103400.96 | CZ21: =+CR21*(BS21*BU21+BW21*BY21+CA21*CC21)*0.3025 -> 2658697.2 | DA21: =+(BS21*BT21+BW21*BX21+CA21*CB21) -> 677708.59 | DB21: =+CS21*(BS21*BT21+BW21*BX21+CA21*CB21)*0.3025 -> 17015568
A22: 압구정3구역 | B22: 서울특별시 강남구 압구정동 369-1 | C22: 45992 | D22: 서울특별시 강남구공고 제 2025-2711호 | E22: 1414453 | F22: 구글링 | H22: =+I22+K22+M22+N22 -> 21108000 | I22: =+J22*CY22*0.3025 -> 2658697.2 | J22: 85 | K22: =+L22*DA22*0.3025 -> 17015568 | L22: 83 | M22: =+CP22 -> 101095.5 | N22: 1332639 | P22: =+Q22+R22 -> 5887500 | Q22: =+T22*E22*0.3025 -> 4528846.2 | R22: =+Q22*S22 -> 1358653.8 | S22: =+BI22 -> 0.3 | T22: =+BJ22 -> 10.584581 | V22: 24930400 | W22: 23069157 | X22: =+V22-W22 -> 1861243 | Z22: 2 | AA22: 1,2차 | AB22: 53 | AC22: 7088 | AD22: 8866 | AE22: 172 | AF22: 46160 | AH22: =+AR22*L22*0.3025 -> 2862.255 | AI22: =+J22*AR22*0.3025 -> 2931.225 | AJ22: =+(H22-P22)/V22 -> 0.61051969 | AL22: 래미안원베일리 | AM22: 서울시 서초구 반포동 1 | AN22: 6700 | AO22: =+AF22 -> 46160 | AP22: 111.79 | AQ22: =+AN22/(AP22*0.3025) -> 198.12828 | AR22: 114 | AS22: 0.2 | AT22: =+AQ22*AR22*(1+AS22)*0.3025 -> 8198.9444 | AU22: =+AD22+AZ22 -> 7400.8915 | AV22: =+AT22-AU22 -> 798.05299 | AZ22: =+AH22-(AC22*AJ22) -> -1465.1085 | BB22: =+AV22/AU22 -> 0.10783201 | BD22: 공사비 뽑아내기 | BF22: 5887500 | BG22: =+BF22/(1+BI22) -> 4528846.2 | BH22: =+BF22-BG22 -> 1358653.8 | BI22: 0.3 | BJ22: =+BG22/(E22*0.3025) -> 10.584581 | BO22: 3934 | BP22: =+BQ22-BO22 -> 600 | BQ22: 4534 | BR22: 522 | BS22: 80 | BT22: =+ROUND(BR22*BO22/BQ22,0) -> 453 | BU22: =+BR22-BT22 -> 69 | BV22: 486 | BW22: 114 | BX22: =+ROUND(BV22*BO22/BQ22,0) -> 422 | BY22: =+BV22-BX22 -> 64 | BZ22: 3526 | CA22: =+CW22 -> 193.97208 | CB22: =+ROUND(BZ22*BO22/BQ22,0) -> 3059 | CC22: =+BZ22-CB22 -> 467 | CE22: 641 | CG22: 511 | CH22: =+BS22 -> 80 | CI22: 130 | CJ22: =+BW22 -> 114 | CK22: =+BQ22+CE22+CF22 -> 5175 | CM22: 6 | CN22: 21108000 | CO22: =+N22 -> 1332639 | CP22: =+CM22*(CG22*CH22+CI22*CJ22)*0.3025 -> 101095.5 | CQ22: =+CN22-CO22-CP22 -> 19674266 | CR22: =+J22 -> 85 | CS22: =+L22 -> 83 | CT22: =+(CR22*BS22*BU22+CS22*BS22*BT22)*0.3025 -> 1051828.8 | CU22: =+(CR22*BW22*BY22+CS22*BW22*BX22)*0.3025 -> 1395470 | CV22: =+CQ22-CT22-CU22 -> 17226967 | CW22: =+CV22/(CR22*CC22*0.3025+CS22*CB22*0.3025) -> 193.97208 | CY22: =+(BS22*BU22+BW22*BY22+CA22*CC22) -> 103400.96 | CZ22: =+CR22*(BS22*BU22+BW22*BY22+CA22*CC22)*0.3025 -> 2658697.2 | DA22: =+(BS22*BT22+BW22*BX22+CA22*CB22) -> 677708.59 | DB22: =+CS22*(BS22*BT22+BW22*BX22+CA22*CB22)*0.3025 -> 17015568
A23: 압구정3구역 | B23: 서울특별시 강남구 압구정동 369-1 | C23: 45992 | D23: 서울특별시 강남구공고 제 2025-2711호 | E23: 1414453 | F23: 구글링 | H23: =+I23+K23+M23+N23 -> 21108000 | I23: =+J23*CY23*0.3025 -> 2658697.2 | J23: 85 | K23: =+L23*DA23*0.3025 -> 17015568 | L23: 83 | M23: =+CP23 -> 101095.5 | N23: 1332639 | P23: =+Q23+R23 -> 5887500 | Q23: =+T23*E23*0.3025 -> 4528846.2 | R23: =+Q23*S23 -> 1358653.8 | S23: =+BI23 -> 0.3 | T23: =+BJ23 -> 10.584581 | V23: 24930400 | W23: 23069157 | X23: =+V23-W23 -> 1861243 | Z23: 3 | AA23: 1,2차 | AB23: 54 | AC23: 6928 | AD23: 8166 | AE23: 176 | AF23: 46160 | AH23: =+AR23*L23*0.3025 -> 2862.255 | AI23: =+J23*AR23*0.3025 -> 2931.225 | AJ23: =+(H23-P23)/V23 -> 0.61051969 | AL23: 래미안원베일리 | AM23: 서울시 서초구 반포동 1 | AN23: 6700 | AO23: =+AF23 -> 46160 | AP23: 111.79 | AQ23: =+AN23/(AP23*0.3025) -> 198.12828 | AR23: 114 | AS23: 0.2 | AT23: =+AQ23*AR23*(1+AS23)*0.3025 -> 8198.9444 | AU23: =+AD23+AZ23 -> 6798.5746 | AV23: =+AT23-AU23 -> 1400.3698 | AZ23: =+AH23-(AC23*AJ23) -> -1367.4254 | BB23: =+AV23/AU23 -> 0.20597992 | BD23: 공사비 뽑아내기 | BF23: 5887500 | BG23: =+BF23/(1+BI23) -> 4528846.2 | BH23: =+BF23-BG23 -> 1358653.8 | BI23: 0.3 | BJ23: =+BG23/(E23*0.3025) -> 10.584581 | BO23: 3934 | BP23: =+BQ23-BO23 -> 600 | BQ23: 4534 | BR23: 522 | BS23: 80 | BT23: =+ROUND(BR23*BO23/BQ23,0) -> 453 | BU23: =+BR23-BT23 -> 69 | BV23: 486 | BW23: 114 | BX23: =+ROUND(BV23*BO23/BQ23,0) -> 422 | BY23: =+BV23-BX23 -> 64 | BZ23: 3526 | CA23: =+CW23 -> 193.97208 | CB23: =+ROUND(BZ23*BO23/BQ23,0) -> 3059 | CC23: =+BZ23-CB23 -> 467 | CE23: 641 | CG23: 511 | CH23: =+BS23 -> 80 | CI23: 130 | CJ23: =+BW23 -> 114 | CK23: =+BQ23+CE23+CF23 -> 5175 | CM23: 6 | CN23: 21108000 | CO23: =+N23 -> 1332639 | CP23: =+CM23*(CG23*CH23+CI23*CJ23)*0.3025 -> 101095.5 | CQ23: =+CN23-CO23-CP23 -> 19674266 | CR23: =+J23 -> 85 | CS23: =+L23 -> 83 | CT23: =+(CR23*BS23*BU23+CS23*BS23*BT23)*0.3025 -> 1051828.8 | CU23: =+(CR23*BW23*BY23+CS23*BW23*BX23)*0.3025 -> 1395470 | CV23: =+CQ23-CT23-CU23 -> 17226967 | CW23: =+CV23/(CR23*CC23*0.3025+CS23*CB23*0.3025) -> 193.97208 | CY23: =+(BS23*BU23+BW23*BY23+CA23*CC23) -> 103400.96 | CZ23: =+CR23*(BS23*BU23+BW23*BY23+CA23*CC23)*0.3025 -> 2658697.2 | DA23: =+(BS23*BT23+BW23*BX23+CA23*CB23) -> 677708.59 | DB23: =+CS23*(BS23*BT23+BW23*BX23+CA23*CB23)*0.3025 -> 17015568
A24: 압구정3구역 | B24: 서울특별시 강남구 압구정동 369-1 | C24: 45992 | D24: 서울특별시 강남구공고 제 2025-2711호 | E24: 1414453 | F24: 구글링 | H24: =+I24+K24+M24+N24 -> 21108000 | I24: =+J24*CY24*0.3025 -> 2658697.2 | J24: 85 | K24: =+L24*DA24*0.3025 -> 17015568 | L24: 83 | M24: =+CP24 -> 101095.5 | N24: 1332639 | P24: =+Q24+R24 -> 5887500 | Q24: =+T24*E24*0.3025 -> 4528846.2 | R24: =+Q24*S24 -> 1358653.8 | S24: =+BI24 -> 0.3 | T24: =+BJ24 -> 10.584581 | V24: 24930400 | W24: 23069157 | X24: =+V24-W24 -> 1861243 | Z24: 4 | AA24: 1,2차 | AB24: 65 | AC24: 8328 | AD24: 10666 | AE24: 211 | AF24: 46160 | AH24: =+AR24*L24*0.3025 -> 2862.255 | AI24: =+J24*AR24*0.3025 -> 2931.225 | AJ24: =+(H24-P24)/V24 -> 0.61051969 | AL24: 래미안원베일리 | AM24: 서울시 서초구 반포동 1 | AN24: 6700 | AO24: =+AF24 -> 46160 | AP24: 111.79 | AQ24: =+AN24/(AP24*0.3025) -> 198.12828 | AR24: 114 | AS24: 0.2 | AT24: =+AQ24*AR24*(1+AS24)*0.3025 -> 8198.9444 | AU24: =+AD24+AZ24 -> 8443.847 | AV24: =+AT24-AU24 -> -244.9026 | AZ24: =+AH24-(AC24*AJ24) -> -2222.153 | BB24: =+AV24/AU24 -> -0.029003675 | BD24: 공사비 뽑아내기 | BF24: 5887500 | BG24: =+BF24/(1+BI24) -> 4528846.2 | BH24: =+BF24-BG24 -> 1358653.8 | BI24: 0.3 | BJ24: =+BG24/(E24*0.3025) -> 10.584581 | BO24: 3934 | BP24: =+BQ24-BO24 -> 600 | BQ24: 4534 | BR24: 522 | BS24: 80 | BT24: =+ROUND(BR24*BO24/BQ24,0) -> 453 | BU24: =+BR24-BT24 -> 69 | BV24: 486 | BW24: 114 | BX24: =+ROUND(BV24*BO24/BQ24,0) -> 422 | BY24: =+BV24-BX24 -> 64 | BZ24: 3526 | CA24: =+CW24 -> 193.97208 | CB24: =+ROUND(BZ24*BO24/BQ24,0) -> 3059 | CC24: =+BZ24-CB24 -> 467 | CE24: 641 | CG24: 511 | CH24: =+BS24 -> 80 | CI24: 130 | CJ24: =+BW24 -> 114 | CK24: =+BQ24+CE24+CF24 -> 5175 | CM24: 6 | CN24: 21108000 | CO24: =+N24 -> 1332639 | CP24: =+CM24*(CG24*CH24+CI24*CJ24)*0.3025 -> 101095.5 | CQ24: =+CN24-CO24-CP24 -> 19674266 | CR24: =+J24 -> 85 | CS24: =+L24 -> 83 | CT24: =+(CR24*BS24*BU24+CS24*BS24*BT24)*0.3025 -> 1051828.8 | CU24: =+(CR24*BW24*BY24+CS24*BW24*BX24)*0.3025 -> 1395470 | CV24: =+CQ24-CT24-CU24 -> 17226967 | CW24: =+CV24/(CR24*CC24*0.3025+CS24*CB24*0.3025) -> 193.97208 | CY24: =+(BS24*BU24+BW24*BY24+CA24*CC24) -> 103400.96 | CZ24: =+CR24*(BS24*BU24+BW24*BY24+CA24*CC24)*0.3025 -> 2658697.2 | DA24: =+(BS24*BT24+BW24*BX24+CA24*CB24) -> 677708.59 | DB24: =+CS24*(BS24*BT24+BW24*BX24+CA24*CB24)*0.3025 -> 17015568
A25: 압구정3구역 | B25: 서울특별시 강남구 압구정동 369-1 | C25: 45992 | D25: 서울특별시 강남구공고 제 2025-2711호 | E25: 1414453 | F25: 구글링 | H25: =+I25+K25+M25+N25 -> 21108000 | I25: =+J25*CY25*0.3025 -> 2658697.2 | J25: 85 | K25: =+L25*DA25*0.3025 -> 17015568 | L25: 83 | M25: =+CP25 -> 101095.5 | N25: 1332639 | P25: =+Q25+R25 -> 5887500 | Q25: =+T25*E25*0.3025 -> 4528846.2 | R25: =+Q25*S25 -> 1358653.8 | S25: =+BI25 -> 0.3 | T25: =+BJ25 -> 10.584581 | V25: 24930400 | W25: 23069157 | X25: =+V25-W25 -> 1861243 | Z25: 5 | AA25: 3차 | AB25: 33 | AC25: 4091 | AD25: 5150 | AE25: 108 | AF25: 46160 | AH25: =+AR25*L25*0.3025 -> 2862.255 | AI25: =+J25*AR25*0.3025 -> 2931.225 | AJ25: =+(H25-P25)/V25 -> 0.61051969 | AL25: 래미안원베일리 | AM25: 서울시 서초구 반포동 1 | AN25: 6700 | AO25: =+AF25 -> 46160 | AP25: 111.79 | AQ25: =+AN25/(AP25*0.3025) -> 198.12828 | AR25: 114 | AS25: 0.2 | AT25: =+AQ25*AR25*(1+AS25)*0.3025 -> 8198.9444 | AU25: =+AD25+AZ25 -> 5514.619 | AV25: =+AT25-AU25 -> 2684.3255 | AZ25: =+AH25-(AC25*AJ25) -> 364.61896 | BB25: =+AV25/AU25 -> 0.48676536 | BD25: 공사비 뽑아내기 | BF25: 5887500 | BG25: =+BF25/(1+BI25) -> 4528846.2 | BH25: =+BF25-BG25 -> 1358653.8 | BI25: 0.3 | BJ25: =+BG25/(E25*0.3025) -> 10.584581 | BO25: 3934 | BP25: =+BQ25-BO25 -> 600 | BQ25: 4534 | BR25: 522 | BS25: 80 | BT25: =+ROUND(BR25*BO25/BQ25,0) -> 453 | BU25: =+BR25-BT25 -> 69 | BV25: 486 | BW25: 114 | BX25: =+ROUND(BV25*BO25/BQ25,0) -> 422 | BY25: =+BV25-BX25 -> 64 | BZ25: 3526 | CA25: =+CW25 -> 193.97208 | CB25: =+ROUND(BZ25*BO25/BQ25,0) -> 3059 | CC25: =+BZ25-CB25 -> 467 | CE25: 641 | CG25: 511 | CH25: =+BS25 -> 80 | CI25: 130 | CJ25: =+BW25 -> 114 | CK25: =+BQ25+CE25+CF25 -> 5175 | CM25: 6 | CN25: 21108000 | CO25: =+N25 -> 1332639 | CP25: =+CM25*(CG25*CH25+CI25*CJ25)*0.3025 -> 101095.5 | CQ25: =+CN25-CO25-CP25 -> 19674266 | CR25: =+J25 -> 85 | CS25: =+L25 -> 83 | CT25: =+(CR25*BS25*BU25+CS25*BS25*BT25)*0.3025 -> 1051828.8 | CU25: =+(CR25*BW25*BY25+CS25*BW25*BX25)*0.3025 -> 1395470 | CV25: =+CQ25-CT25-CU25 -> 17226967 | CW25: =+CV25/(CR25*CC25*0.3025+CS25*CB25*0.3025) -> 193.97208 | CY25: =+(BS25*BU25+BW25*BY25+CA25*CC25) -> 103400.96 | CZ25: =+CR25*(BS25*BU25+BW25*BY25+CA25*CC25)*0.3025 -> 2658697.2 | DA25: =+(BS25*BT25+BW25*BX25+CA25*CB25) -> 677708.59 | DB25: =+CS25*(BS25*BT25+BW25*BX25+CA25*CB25)*0.3025 -> 17015568
A26: 압구정3구역 | B26: 서울특별시 강남구 압구정동 369-1 | C26: 45992 | D26: 서울특별시 강남구공고 제 2025-2711호 | E26: 1414453 | F26: 구글링 | H26: =+I26+K26+M26+N26 -> 21108000 | I26: =+J26*CY26*0.3025 -> 2658697.2 | J26: 85 | K26: =+L26*DA26*0.3025 -> 17015568 | L26: 83 | M26: =+CP26 -> 101095.5 | N26: 1332639 | P26: =+Q26+R26 -> 5887500 | Q26: =+T26*E26*0.3025 -> 4528846.2 | R26: =+Q26*S26 -> 1358653.8 | S26: =+BI26 -> 0.3 | T26: =+BJ26 -> 10.584581 | V26: 24930400 | W26: 23069157 | X26: =+V26-W26 -> 1861243 | Z26: 6 | AA26: 4차 | AB26: 44 | AC26: 5989 | AD26: 7300 | AE26: 140 | AF26: 46160 | AH26: =+AR26*L26*0.3025 -> 2862.255 | AI26: =+J26*AR26*0.3025 -> 2931.225 | AJ26: =+(H26-P26)/V26 -> 0.61051969 | AL26: 래미안원베일리 | AM26: 서울시 서초구 반포동 1 | AN26: 6700 | AO26: =+AF26 -> 46160 | AP26: 111.79 | AQ26: =+AN26/(AP26*0.3025) -> 198.12828 | AR26: 114 | AS26: 0.2 | AT26: =+AQ26*AR26*(1+AS26)*0.3025 -> 8198.9444 | AU26: =+AD26+AZ26 -> 6505.8526 | AV26: =+AT26-AU26 -> 1693.0919 | AZ26: =+AH26-(AC26*AJ26) -> -794.1474 | BB26: =+AV26/AU26 -> 0.26024135 | BD26: 공사비 뽑아내기 | BF26: 5887500 | BG26: =+BF26/(1+BI26) -> 4528846.2 | BH26: =+BF26-BG26 -> 1358653.8 | BI26: 0.3 | BJ26: =+BG26/(E26*0.3025) -> 10.584581 | BO26: 3934 | BP26: =+BQ26-BO26 -> 600 | BQ26: 4534 | BR26: 522 | BS26: 80 | BT26: =+ROUND(BR26*BO26/BQ26,0) -> 453 | BU26: =+BR26-BT26 -> 69 | BV26: 486 | BW26: 114 | BX26: =+ROUND(BV26*BO26/BQ26,0) -> 422 | BY26: =+BV26-BX26 -> 64 | BZ26: 3526 | CA26: =+CW26 -> 193.97208 | CB26: =+ROUND(BZ26*BO26/BQ26,0) -> 3059 | CC26: =+BZ26-CB26 -> 467 | CE26: 641 | CG26: 511 | CH26: =+BS26 -> 80 | CI26: 130 | CJ26: =+BW26 -> 114 | CK26: =+BQ26+CE26+CF26 -> 5175 | CM26: 6 | CN26: 21108000 | CO26: =+N26 -> 1332639 | CP26: =+CM26*(CG26*CH26+CI26*CJ26)*0.3025 -> 101095.5 | CQ26: =+CN26-CO26-CP26 -> 19674266 | CR26: =+J26 -> 85 | CS26: =+L26 -> 83 | CT26: =+(CR26*BS26*BU26+CS26*BS26*BT26)*0.3025 -> 1051828.8 | CU26: =+(CR26*BW26*BY26+CS26*BW26*BX26)*0.3025 -> 1395470 | CV26: =+CQ26-CT26-CU26 -> 17226967 | CW26: =+CV26/(CR26*CC26*0.3025+CS26*CB26*0.3025) -> 193.97208 | CY26: =+(BS26*BU26+BW26*BY26+CA26*CC26) -> 103400.96 | CZ26: =+CR26*(BS26*BU26+BW26*BY26+CA26*CC26)*0.3025 -> 2658697.2 | DA26: =+(BS26*BT26+BW26*BX26+CA26*CB26) -> 677708.59 | DB26: =+CS26*(BS26*BT26+BW26*BX26+CA26*CB26)*0.3025 -> 17015568
A27: 압구정3구역 | B27: 서울특별시 강남구 압구정동 369-1 | C27: 45992 | D27: 서울특별시 강남구공고 제 2025-2711호 | E27: 1414453 | F27: 구글링 | H27: =+I27+K27+M27+N27 -> 21108000 | I27: =+J27*CY27*0.3025 -> 2658697.2 | J27: 85 | K27: =+L27*DA27*0.3025 -> 17015568 | L27: 83 | M27: =+CP27 -> 101095.5 | N27: 1332639 | P27: =+Q27+R27 -> 5887500 | Q27: =+T27*E27*0.3025 -> 4528846.2 | R27: =+Q27*S27 -> 1358653.8 | S27: =+BI27 -> 0.3 | T27: =+BJ27 -> 10.584581 | V27: 24930400 | W27: 23069157 | X27: =+V27-W27 -> 1861243 | Z27: 7 | AA27: 5차 | AB27: 35 | AC27: 4259 | AD27: 6100 | AE27: 113 | AF27: 46160 | AH27: =+AR27*L27*0.3025 -> 2862.255 | AI27: =+J27*AR27*0.3025 -> 2931.225 | AJ27: =+(H27-P27)/V27 -> 0.61051969 | AL27: 래미안원베일리 | AM27: 서울시 서초구 반포동 1 | AN27: 6700 | AO27: =+AF27 -> 46160 | AP27: 111.79 | AQ27: =+AN27/(AP27*0.3025) -> 198.12828 | AR27: 114 | AS27: 0.2 | AT27: =+AQ27*AR27*(1+AS27)*0.3025 -> 8198.9444 | AU27: =+AD27+AZ27 -> 6362.0517 | AV27: =+AT27-AU27 -> 1836.8928 | AZ27: =+AH27-(AC27*AJ27) -> 262.05165 | BB27: =+AV27/AU27 -> 0.28872648 | BD27: 공사비 뽑아내기 | BF27: 5887500 | BG27: =+BF27/(1+BI27) -> 4528846.2 | BH27: =+BF27-BG27 -> 1358653.8 | BI27: 0.3 | BJ27: =+BG27/(E27*0.3025) -> 10.584581 | BO27: 3934 | BP27: =+BQ27-BO27 -> 600 | BQ27: 4534 | BR27: 522 | BS27: 80 | BT27: =+ROUND(BR27*BO27/BQ27,0) -> 453 | BU27: =+BR27-BT27 -> 69 | BV27: 486 | BW27: 114 | BX27: =+ROUND(BV27*BO27/BQ27,0) -> 422 | BY27: =+BV27-BX27 -> 64 | BZ27: 3526 | CA27: =+CW27 -> 193.97208 | CB27: =+ROUND(BZ27*BO27/BQ27,0) -> 3059 | CC27: =+BZ27-CB27 -> 467 | CE27: 641 | CG27: 511 | CH27: =+BS27 -> 80 | CI27: 130 | CJ27: =+BW27 -> 114 | CK27: =+BQ27+CE27+CF27 -> 5175 | CM27: 6 | CN27: 21108000 | CO27: =+N27 -> 1332639 | CP27: =+CM27*(CG27*CH27+CI27*CJ27)*0.3025 -> 101095.5 | CQ27: =+CN27-CO27-CP27 -> 19674266 | CR27: =+J27 -> 85 | CS27: =+L27 -> 83 | CT27: =+(CR27*BS27*BU27+CS27*BS27*BT27)*0.3025 -> 1051828.8 | CU27: =+(CR27*BW27*BY27+CS27*BW27*BX27)*0.3025 -> 1395470 | CV27: =+CQ27-CT27-CU27 -> 17226967 | CW27: =+CV27/(CR27*CC27*0.3025+CS27*CB27*0.3025) -> 193.97208 | CY27: =+(BS27*BU27+BW27*BY27+CA27*CC27) -> 103400.96 | CZ27: =+CR27*(BS27*BU27+BW27*BY27+CA27*CC27)*0.3025 -> 2658697.2 | DA27: =+(BS27*BT27+BW27*BX27+CA27*CB27) -> 677708.59 | DB27: =+CS27*(BS27*BT27+BW27*BX27+CA27*CB27)*0.3025 -> 17015568
A28: 압구정3구역 | B28: 서울특별시 강남구 압구정동 369-1 | C28: 45992 | D28: 서울특별시 강남구공고 제 2025-2711호 | E28: 1414453 | F28: 구글링 | H28: =+I28+K28+M28+N28 -> 21108000 | I28: =+J28*CY28*0.3025 -> 2658697.2 | J28: 85 | K28: =+L28*DA28*0.3025 -> 17015568 | L28: 83 | M28: =+CP28 -> 101095.5 | N28: 1332639 | P28: =+Q28+R28 -> 5887500 | Q28: =+T28*E28*0.3025 -> 4528846.2 | R28: =+Q28*S28 -> 1358653.8 | S28: =+BI28 -> 0.3 | T28: =+BJ28 -> 10.584581 | V28: 24930400 | W28: 23069157 | X28: =+V28-W28 -> 1861243 | Z28: 8 | AA28: 6,7차 | AB28: 48 | AC28: 5798 | AD28: 7400 | AE28: 156 | AF28: 46160 | AH28: =+AR28*L28*0.3025 -> 2862.255 | AI28: =+J28*AR28*0.3025 -> 2931.225 | AJ28: =+(H28-P28)/V28 -> 0.61051969 | AL28: 래미안원베일리 | AM28: 서울시 서초구 반포동 1 | AN28: 6700 | AO28: =+AF28 -> 46160 | AP28: 111.79 | AQ28: =+AN28/(AP28*0.3025) -> 198.12828 | AR28: 114 | AS28: 0.2 | AT28: =+AQ28*AR28*(1+AS28)*0.3025 -> 8198.9444 | AU28: =+AD28+AZ28 -> 6722.4619 | AV28: =+AT28-AU28 -> 1476.4826 | AZ28: =+AH28-(AC28*AJ28) -> -677.53814 | BB28: =+AV28/AU28 -> 0.21963421 | BD28: 공사비 뽑아내기 | BF28: 5887500 | BG28: =+BF28/(1+BI28) -> 4528846.2 | BH28: =+BF28-BG28 -> 1358653.8 | BI28: 0.3 | BJ28: =+BG28/(E28*0.3025) -> 10.584581 | BO28: 3934 | BP28: =+BQ28-BO28 -> 600 | BQ28: 4534 | BR28: 522 | BS28: 80 | BT28: =+ROUND(BR28*BO28/BQ28,0) -> 453 | BU28: =+BR28-BT28 -> 69 | BV28: 486 | BW28: 114 | BX28: =+ROUND(BV28*BO28/BQ28,0) -> 422 | BY28: =+BV28-BX28 -> 64 | BZ28: 3526 | CA28: =+CW28 -> 193.97208 | CB28: =+ROUND(BZ28*BO28/BQ28,0) -> 3059 | CC28: =+BZ28-CB28 -> 467 | CE28: 641 | CG28: 511 | CH28: =+BS28 -> 80 | CI28: 130 | CJ28: =+BW28 -> 114 | CK28: =+BQ28+CE28+CF28 -> 5175 | CM28: 6 | CN28: 21108000 | CO28: =+N28 -> 1332639 | CP28: =+CM28*(CG28*CH28+CI28*CJ28)*0.3025 -> 101095.5 | CQ28: =+CN28-CO28-CP28 -> 19674266 | CR28: =+J28 -> 85 | CS28: =+L28 -> 83 | CT28: =+(CR28*BS28*BU28+CS28*BS28*BT28)*0.3025 -> 1051828.8 | CU28: =+(CR28*BW28*BY28+CS28*BW28*BX28)*0.3025 -> 1395470 | CV28: =+CQ28-CT28-CU28 -> 17226967 | CW28: =+CV28/(CR28*CC28*0.3025+CS28*CB28*0.3025) -> 193.97208 | CY28: =+(BS28*BU28+BW28*BY28+CA28*CC28) -> 103400.96 | CZ28: =+CR28*(BS28*BU28+BW28*BY28+CA28*CC28)*0.3025 -> 2658697.2 | DA28: =+(BS28*BT28+BW28*BX28+CA28*CB28) -> 677708.59 | DB28: =+CS28*(BS28*BT28+BW28*BX28+CA28*CB28)*0.3025 -> 17015568
A29: 압구정3구역 | B29: 서울특별시 강남구 압구정동 369-1 | C29: 45992 | D29: 서울특별시 강남구공고 제 2025-2711호 | E29: 1414453 | F29: 구글링 | H29: =+I29+K29+M29+N29 -> 21108000 | I29: =+J29*CY29*0.3025 -> 2658697.2 | J29: 85 | K29: =+L29*DA29*0.3025 -> 17015568 | L29: 83 | M29: =+CP29 -> 101095.5 | N29: 1332639 | P29: =+Q29+R29 -> 5887500 | Q29: =+T29*E29*0.3025 -> 4528846.2 | R29: =+Q29*S29 -> 1358653.8 | S29: =+BI29 -> 0.3 | T29: =+BJ29 -> 10.584581 | V29: 24930400 | W29: 23069157 | X29: =+V29-W29 -> 1861243 | Z29: 9 | AA29: 6,7차 | AB29: 53 | AC29: 6373 | AD29: 8366 | AE29: 170 | AF29: 46160 | AH29: =+AR29*L29*0.3025 -> 2862.255 | AI29: =+J29*AR29*0.3025 -> 2931.225 | AJ29: =+(H29-P29)/V29 -> 0.61051969 | AL29: 래미안원베일리 | AM29: 서울시 서초구 반포동 1 | AN29: 6700 | AO29: =+AF29 -> 46160 | AP29: 111.79 | AQ29: =+AN29/(AP29*0.3025) -> 198.12828 | AR29: 114 | AS29: 0.2 | AT29: =+AQ29*AR29*(1+AS29)*0.3025 -> 8198.9444 | AU29: =+AD29+AZ29 -> 7337.413 | AV29: =+AT29-AU29 -> 861.53141 | AZ29: =+AH29-(AC29*AJ29) -> -1028.587 | BB29: =+AV29/AU29 -> 0.11741624 | BD29: 공사비 뽑아내기 | BF29: 5887500 | BG29: =+BF29/(1+BI29) -> 4528846.2 | BH29: =+BF29-BG29 -> 1358653.8 | BI29: 0.3 | BJ29: =+BG29/(E29*0.3025) -> 10.584581 | BO29: 3934 | BP29: =+BQ29-BO29 -> 600 | BQ29: 4534 | BR29: 522 | BS29: 80 | BT29: =+ROUND(BR29*BO29/BQ29,0) -> 453 | BU29: =+BR29-BT29 -> 69 | BV29: 486 | BW29: 114 | BX29: =+ROUND(BV29*BO29/BQ29,0) -> 422 | BY29: =+BV29-BX29 -> 64 | BZ29: 3526 | CA29: =+CW29 -> 193.97208 | CB29: =+ROUND(BZ29*BO29/BQ29,0) -> 3059 | CC29: =+BZ29-CB29 -> 467 | CE29: 641 | CG29: 511 | CH29: =+BS29 -> 80 | CI29: 130 | CJ29: =+BW29 -> 114 | CK29: =+BQ29+CE29+CF29 -> 5175 | CM29: 6 | CN29: 21108000 | CO29: =+N29 -> 1332639 | CP29: =+CM29*(CG29*CH29+CI29*CJ29)*0.3025 -> 101095.5 | CQ29: =+CN29-CO29-CP29 -> 19674266 | CR29: =+J29 -> 85 | CS29: =+L29 -> 83 | CT29: =+(CR29*BS29*BU29+CS29*BS29*BT29)*0.3025 -> 1051828.8 | CU29: =+(CR29*BW29*BY29+CS29*BW29*BX29)*0.3025 -> 1395470 | CV29: =+CQ29-CT29-CU29 -> 17226967 | CW29: =+CV29/(CR29*CC29*0.3025+CS29*CB29*0.3025) -> 193.97208 | CY29: =+(BS29*BU29+BW29*BY29+CA29*CC29) -> 103400.96 | CZ29: =+CR29*(BS29*BU29+BW29*BY29+CA29*CC29)*0.3025 -> 2658697.2 | DA29: =+(BS29*BT29+BW29*BX29+CA29*CB29) -> 677708.59 | DB29: =+CS29*(BS29*BT29+BW29*BX29+CA29*CB29)*0.3025 -> 17015568
A30: 압구정3구역 | B30: 서울특별시 강남구 압구정동 369-1 | C30: 45992 | D30: 서울특별시 강남구공고 제 2025-2711호 | E30: 1414453 | F30: 구글링 | H30: =+I30+K30+M30+N30 -> 21108000 | I30: =+J30*CY30*0.3025 -> 2658697.2 | J30: 85 | K30: =+L30*DA30*0.3025 -> 17015568 | L30: 83 | M30: =+CP30 -> 101095.5 | N30: 1332639 | P30: =+Q30+R30 -> 5887500 | Q30: =+T30*E30*0.3025 -> 4528846.2 | R30: =+Q30*S30 -> 1358653.8 | S30: =+BI30 -> 0.3 | T30: =+BJ30 -> 10.584581 | V30: 24930400 | W30: 23069157 | X30: =+V30-W30 -> 1861243 | Z30: 10 | AA30: 6,7차 | AB30: 65 | AC30: 7979 | AD30: 9800 | AE30: 212 | AF30: 46160 | AH30: =+AR30*L30*0.3025 -> 2862.255 | AI30: =+J30*AR30*0.3025 -> 2931.225 | AJ30: =+(H30-P30)/V30 -> 0.61051969 | AL30: 래미안원베일리 | AM30: 서울시 서초구 반포동 1 | AN30: 6700 | AO30: =+AF30 -> 46160 | AP30: 111.79 | AQ30: =+AN30/(AP30*0.3025) -> 198.12828 | AR30: 114 | AS30: 0.2 | AT30: =+AQ30*AR30*(1+AS30)*0.3025 -> 8198.9444 | AU30: =+AD30+AZ30 -> 7790.9184 | AV30: =+AT30-AU30 -> 408.02603 | AZ30: =+AH30-(AC30*AJ30) -> -2009.0816 | BB30: =+AV30/AU30 -> 0.052372007 | BD30: 공사비 뽑아내기 | BF30: 5887500 | BG30: =+BF30/(1+BI30) -> 4528846.2 | BH30: =+BF30-BG30 -> 1358653.8 | BI30: 0.3 | BJ30: =+BG30/(E30*0.3025) -> 10.584581 | BO30: 3934 | BP30: =+BQ30-BO30 -> 600 | BQ30: 4534 | BR30: 522 | BS30: 80 | BT30: =+ROUND(BR30*BO30/BQ30,0) -> 453 | BU30: =+BR30-BT30 -> 69 | BV30: 486 | BW30: 114 | BX30: =+ROUND(BV30*BO30/BQ30,0) -> 422 | BY30: =+BV30-BX30 -> 64 | BZ30: 3526 | CA30: =+CW30 -> 193.97208 | CB30: =+ROUND(BZ30*BO30/BQ30,0) -> 3059 | CC30: =+BZ30-CB30 -> 467 | CE30: 641 | CG30: 511 | CH30: =+BS30 -> 80 | CI30: 130 | CJ30: =+BW30 -> 114 | CK30: =+BQ30+CE30+CF30 -> 5175 | CM30: 6 | CN30: 21108000 | CO30: =+N30 -> 1332639 | CP30: =+CM30*(CG30*CH30+CI30*CJ30)*0.3025 -> 101095.5 | CQ30: =+CN30-CO30-CP30 -> 19674266 | CR30: =+J30 -> 85 | CS30: =+L30 -> 83 | CT30: =+(CR30*BS30*BU30+CS30*BS30*BT30)*0.3025 -> 1051828.8 | CU30: =+(CR30*BW30*BY30+CS30*BW30*BX30)*0.3025 -> 1395470 | CV30: =+CQ30-CT30-CU30 -> 17226967 | CW30: =+CV30/(CR30*CC30*0.3025+CS30*CB30*0.3025) -> 193.97208 | CY30: =+(BS30*BU30+BW30*BY30+CA30*CC30) -> 103400.96 | CZ30: =+CR30*(BS30*BU30+BW30*BY30+CA30*CC30)*0.3025 -> 2658697.2 | DA30: =+(BS30*BT30+BW30*BX30+CA30*CB30) -> 677708.59 | DB30: =+CS30*(BS30*BT30+BW30*BX30+CA30*CB30)*0.3025 -> 17015568
A31: 압구정3구역 | B31: 서울특별시 강남구 압구정동 369-1 | C31: 45992 | D31: 서울특별시 강남구공고 제 2025-2711호 | E31: 1414453 | F31: 구글링 | H31: =+I31+K31+M31+N31 -> 21108000 | I31: =+J31*CY31*0.3025 -> 2658697.2 | J31: 85 | K31: =+L31*DA31*0.3025 -> 17015568 | L31: 83 | M31: =+CP31 -> 101095.5 | N31: 1332639 | P31: =+Q31+R31 -> 5887500 | Q31: =+T31*E31*0.3025 -> 4528846.2 | R31: =+Q31*S31 -> 1358653.8 | S31: =+BI31 -> 0.3 | T31: =+BJ31 -> 10.584581 | V31: 24930400 | W31: 23069157 | X31: =+V31-W31 -> 1861243 | Z31: 11 | AA31: 6,7차 | AB31: 80 | AC31: 9995 | AD31: 12500 | AE31: 264 | AF31: 46160 | AH31: =+AR31*L31*0.3025 -> 2862.255 | AI31: =+J31*AR31*0.3025 -> 2931.225 | AJ31: =+(H31-P31)/V31 -> 0.61051969 | AL31: 래미안원베일리 | AM31: 서울시 서초구 반포동 1 | AN31: 6700 | AO31: =+AF31 -> 46160 | AP31: 111.79 | AQ31: =+AN31/(AP31*0.3025) -> 198.12828 | AR31: 114 | AS31: 0.2 | AT31: =+AQ31*AR31*(1+AS31)*0.3025 -> 8198.9444 | AU31: =+AD31+AZ31 -> 9260.1107 | AV31: =+AT31-AU31 -> -1061.1663 | AZ31: =+AH31-(AC31*AJ31) -> -3239.8893 | BB31: =+AV31/AU31 -> -0.11459542 | BD31: 공사비 뽑아내기 | BF31: 5887500 | BG31: =+BF31/(1+BI31) -> 4528846.2 | BH31: =+BF31-BG31 -> 1358653.8 | BI31: 0.3 | BJ31: =+BG31/(E31*0.3025) -> 10.584581 | BO31: 3934 | BP31: =+BQ31-BO31 -> 600 | BQ31: 4534 | BR31: 522 | BS31: 80 | BT31: =+ROUND(BR31*BO31/BQ31,0) -> 453 | BU31: =+BR31-BT31 -> 69 | BV31: 486 | BW31: 114 | BX31: =+ROUND(BV31*BO31/BQ31,0) -> 422 | BY31: =+BV31-BX31 -> 64 | BZ31: 3526 | CA31: =+CW31 -> 193.97208 | CB31: =+ROUND(BZ31*BO31/BQ31,0) -> 3059 | CC31: =+BZ31-CB31 -> 467 | CE31: 641 | CG31: 511 | CH31: =+BS31 -> 80 | CI31: 130 | CJ31: =+BW31 -> 114 | CK31: =+BQ31+CE31+CF31 -> 5175 | CM31: 6 | CN31: 21108000 | CO31: =+N31 -> 1332639 | CP31: =+CM31*(CG31*CH31+CI31*CJ31)*0.3025 -> 101095.5 | CQ31: =+CN31-CO31-CP31 -> 19674266 | CR31: =+J31 -> 85 | CS31: =+L31 -> 83 | CT31: =+(CR31*BS31*BU31+CS31*BS31*BT31)*0.3025 -> 1051828.8 | CU31: =+(CR31*BW31*BY31+CS31*BW31*BX31)*0.3025 -> 1395470 | CV31: =+CQ31-CT31-CU31 -> 17226967 | CW31: =+CV31/(CR31*CC31*0.3025+CS31*CB31*0.3025) -> 193.97208 | CY31: =+(BS31*BU31+BW31*BY31+CA31*CC31) -> 103400.96 | CZ31: =+CR31*(BS31*BU31+BW31*BY31+CA31*CC31)*0.3025 -> 2658697.2 | DA31: =+(BS31*BT31+BW31*BX31+CA31*CB31) -> 677708.59 | DB31: =+CS31*(BS31*BT31+BW31*BX31+CA31*CB31)*0.3025 -> 17015568
A32: 압구정3구역 | B32: 서울특별시 강남구 압구정동 369-1 | C32: 45992 | D32: 서울특별시 강남구공고 제 2025-2711호 | E32: 1414453 | F32: 구글링 | H32: =+I32+K32+M32+N32 -> 21108000 | I32: =+J32*CY32*0.3025 -> 2658697.2 | J32: 85 | K32: =+L32*DA32*0.3025 -> 17015568 | L32: 83 | M32: =+CP32 -> 101095.5 | N32: 1332639 | P32: =+Q32+R32 -> 5887500 | Q32: =+T32*E32*0.3025 -> 4528846.2 | R32: =+Q32*S32 -> 1358653.8 | S32: =+BI32 -> 0.3 | T32: =+BJ32 -> 10.584581 | V32: 24930400 | W32: 23069157 | X32: =+V32-W32 -> 1861243 | Z32: 12 | AA32: 10차 | AB32: 36 | AC32: 4337 | AD32: 6200 | AE32: 115 | AF32: 46160 | AH32: =+AR32*L32*0.3025 -> 2862.255 | AI32: =+J32*AR32*0.3025 -> 2931.225 | AJ32: =+(H32-P32)/V32 -> 0.61051969 | AL32: 래미안원베일리 | AM32: 서울시 서초구 반포동 1 | AN32: 6700 | AO32: =+AF32 -> 46160 | AP32: 111.79 | AQ32: =+AN32/(AP32*0.3025) -> 198.12828 | AR32: 114 | AS32: 0.2 | AT32: =+AQ32*AR32*(1+AS32)*0.3025 -> 8198.9444 | AU32: =+AD32+AZ32 -> 6414.4311 | AV32: =+AT32-AU32 -> 1784.5133 | AZ32: =+AH32-(AC32*AJ32) -> 214.43112 | BB32: =+AV32/AU32 -> 0.2782029 | BD32: 공사비 뽑아내기 | BF32: 5887500 | BG32: =+BF32/(1+BI32) -> 4528846.2 | BH32: =+BF32-BG32 -> 1358653.8 | BI32: 0.3 | BJ32: =+BG32/(E32*0.3025) -> 10.584581 | BO32: 3934 | BP32: =+BQ32-BO32 -> 600 | BQ32: 4534 | BR32: 522 | BS32: 80 | BT32: =+ROUND(BR32*BO32/BQ32,0) -> 453 | BU32: =+BR32-BT32 -> 69 | BV32: 486 | BW32: 114 | BX32: =+ROUND(BV32*BO32/BQ32,0) -> 422 | BY32: =+BV32-BX32 -> 64 | BZ32: 3526 | CA32: =+CW32 -> 193.97208 | CB32: =+ROUND(BZ32*BO32/BQ32,0) -> 3059 | CC32: =+BZ32-CB32 -> 467 | CE32: 641 | CG32: 511 | CH32: =+BS32 -> 80 | CI32: 130 | CJ32: =+BW32 -> 114 | CK32: =+BQ32+CE32+CF32 -> 5175 | CM32: 6 | CN32: 21108000 | CO32: =+N32 -> 1332639 | CP32: =+CM32*(CG32*CH32+CI32*CJ32)*0.3025 -> 101095.5 | CQ32: =+CN32-CO32-CP32 -> 19674266 | CR32: =+J32 -> 85 | CS32: =+L32 -> 83 | CT32: =+(CR32*BS32*BU32+CS32*BS32*BT32)*0.3025 -> 1051828.8 | CU32: =+(CR32*BW32*BY32+CS32*BW32*BX32)*0.3025 -> 1395470 | CV32: =+CQ32-CT32-CU32 -> 17226967 | CW32: =+CV32/(CR32*CC32*0.3025+CS32*CB32*0.3025) -> 193.97208 | CY32: =+(BS32*BU32+BW32*BY32+CA32*CC32) -> 103400.96 | CZ32: =+CR32*(BS32*BU32+BW32*BY32+CA32*CC32)*0.3025 -> 2658697.2 | DA32: =+(BS32*BT32+BW32*BX32+CA32*CB32) -> 677708.59 | DB32: =+CS32*(BS32*BT32+BW32*BX32+CA32*CB32)*0.3025 -> 17015568
A33: 압구정3구역 | B33: 서울특별시 강남구 압구정동 369-1 | C33: 45992 | D33: 서울특별시 강남구공고 제 2025-2711호 | E33: 1414453 | F33: 구글링 | H33: =+I33+K33+M33+N33 -> 21108000 | I33: =+J33*CY33*0.3025 -> 2658697.2 | J33: 85 | K33: =+L33*DA33*0.3025 -> 17015568 | L33: 83 | M33: =+CP33 -> 101095.5 | N33: 1332639 | P33: =+Q33+R33 -> 5887500 | Q33: =+T33*E33*0.3025 -> 4528846.2 | R33: =+Q33*S33 -> 1358653.8 | S33: =+BI33 -> 0.3 | T33: =+BJ33 -> 10.584581 | V33: 24930400 | W33: 23069157 | X33: =+V33-W33 -> 1861243 | Z33: 13 | AA33: 10차 | AB33: 50 | AC33: 6145 | AD33: 7650 | AE33: 164 | AF33: 46160 | AH33: =+AR33*L33*0.3025 -> 2862.255 | AI33: =+J33*AR33*0.3025 -> 2931.225 | AJ33: =+(H33-P33)/V33 -> 0.61051969 | AL33: 래미안원베일리 | AM33: 서울시 서초구 반포동 1 | AN33: 6700 | AO33: =+AF33 -> 46160 | AP33: 111.79 | AQ33: =+AN33/(AP33*0.3025) -> 198.12828 | AR33: 114 | AS33: 0.2 | AT33: =+AQ33*AR33*(1+AS33)*0.3025 -> 8198.9444 | AU33: =+AD33+AZ33 -> 6760.6115 | AV33: =+AT33-AU33 -> 1438.3329 | AZ33: =+AH33-(AC33*AJ33) -> -889.38848 | BB33: =+AV33/AU33 -> 0.2127519 | BD33: 공사비 뽑아내기 | BF33: 5887500 | BG33: =+BF33/(1+BI33) -> 4528846.2 | BH33: =+BF33-BG33 -> 1358653.8 | BI33: 0.3 | BJ33: =+BG33/(E33*0.3025) -> 10.584581 | BO33: 3934 | BP33: =+BQ33-BO33 -> 600 | BQ33: 4534 | BR33: 522 | BS33: 80 | BT33: =+ROUND(BR33*BO33/BQ33,0) -> 453 | BU33: =+BR33-BT33 -> 69 | BV33: 486 | BW33: 114 | BX33: =+ROUND(BV33*BO33/BQ33,0) -> 422 | BY33: =+BV33-BX33 -> 64 | BZ33: 3526 | CA33: =+CW33 -> 193.97208 | CB33: =+ROUND(BZ33*BO33/BQ33,0) -> 3059 | CC33: =+BZ33-CB33 -> 467 | CE33: 641 | CG33: 511 | CH33: =+BS33 -> 80 | CI33: 130 | CJ33: =+BW33 -> 114 | CK33: =+BQ33+CE33+CF33 -> 5175 | CM33: 6 | CN33: 21108000 | CO33: =+N33 -> 1332639 | CP33: =+CM33*(CG33*CH33+CI33*CJ33)*0.3025 -> 101095.5 | CQ33: =+CN33-CO33-CP33 -> 19674266 | CR33: =+J33 -> 85 | CS33: =+L33 -> 83 | CT33: =+(CR33*BS33*BU33+CS33*BS33*BT33)*0.3025 -> 1051828.8 | CU33: =+(CR33*BW33*BY33+CS33*BW33*BX33)*0.3025 -> 1395470 | CV33: =+CQ33-CT33-CU33 -> 17226967 | CW33: =+CV33/(CR33*CC33*0.3025+CS33*CB33*0.3025) -> 193.97208 | CY33: =+(BS33*BU33+BW33*BY33+CA33*CC33) -> 103400.96 | CZ33: =+CR33*(BS33*BU33+BW33*BY33+CA33*CC33)*0.3025 -> 2658697.2 | DA33: =+(BS33*BT33+BW33*BX33+CA33*CB33) -> 677708.59 | DB33: =+CS33*(BS33*BT33+BW33*BX33+CA33*CB33)*0.3025 -> 17015568
A34: 압구정3구역 | B34: 서울특별시 강남구 압구정동 369-1 | C34: 45992 | D34: 서울특별시 강남구공고 제 2025-2711호 | E34: 1414453 | F34: 구글링 | H34: =+I34+K34+M34+N34 -> 21108000 | I34: =+J34*CY34*0.3025 -> 2658697.2 | J34: 85 | K34: =+L34*DA34*0.3025 -> 17015568 | L34: 83 | M34: =+CP34 -> 101095.5 | N34: 1332639 | P34: =+Q34+R34 -> 5887500 | Q34: =+T34*E34*0.3025 -> 4528846.2 | R34: =+Q34*S34 -> 1358653.8 | S34: =+BI34 -> 0.3 | T34: =+BJ34 -> 10.584581 | V34: 24930400 | W34: 23069157 | X34: =+V34-W34 -> 1861243 | Z34: 14 | AA34: 13차 | AB34: 36A | AC34: 4660 | AD34: 6150 | AE34: 116 | AF34: 46160 | AH34: =+AR34*L34*0.3025 -> 2862.255 | AI34: =+J34*AR34*0.3025 -> 2931.225 | AJ34: =+(H34-P34)/V34 -> 0.61051969 | AL34: 래미안원베일리 | AM34: 서울시 서초구 반포동 1 | AN34: 6700 | AO34: =+AF34 -> 46160 | AP34: 111.79 | AQ34: =+AN34/(AP34*0.3025) -> 198.12828 | AR34: 114 | AS34: 0.2 | AT34: =+AQ34*AR34*(1+AS34)*0.3025 -> 8198.9444 | AU34: =+AD34+AZ34 -> 6167.2333 | AV34: =+AT34-AU34 -> 2031.7112 | AZ34: =+AH34-(AC34*AJ34) -> 17.233259 | BB34: =+AV34/AU34 -> 0.32943641 | BD34: 공사비 뽑아내기 | BF34: 5887500 | BG34: =+BF34/(1+BI34) -> 4528846.2 | BH34: =+BF34-BG34 -> 1358653.8 | BI34: 0.3 | BJ34: =+BG34/(E34*0.3025) -> 10.584581 | BO34: 3934 | BP34: =+BQ34-BO34 -> 600 | BQ34: 4534 | BR34: 522 | BS34: 80 | BT34: =+ROUND(BR34*BO34/BQ34,0) -> 453 | BU34: =+BR34-BT34 -> 69 | BV34: 486 | BW34: 114 | BX34: =+ROUND(BV34*BO34/BQ34,0) -> 422 | BY34: =+BV34-BX34 -> 64 | BZ34: 3526 | CA34: =+CW34 -> 193.97208 | CB34: =+ROUND(BZ34*BO34/BQ34,0) -> 3059 | CC34: =+BZ34-CB34 -> 467 | CE34: 641 | CG34: 511 | CH34: =+BS34 -> 80 | CI34: 130 | CJ34: =+BW34 -> 114 | CK34: =+BQ34+CE34+CF34 -> 5175 | CM34: 6 | CN34: 21108000 | CO34: =+N34 -> 1332639 | CP34: =+CM34*(CG34*CH34+CI34*CJ34)*0.3025 -> 101095.5 | CQ34: =+CN34-CO34-CP34 -> 19674266 | CR34: =+J34 -> 85 | CS34: =+L34 -> 83 | CT34: =+(CR34*BS34*BU34+CS34*BS34*BT34)*0.3025 -> 1051828.8 | CU34: =+(CR34*BW34*BY34+CS34*BW34*BX34)*0.3025 -> 1395470 | CV34: =+CQ34-CT34-CU34 -> 17226967 | CW34: =+CV34/(CR34*CC34*0.3025+CS34*CB34*0.3025) -> 193.97208 | CY34: =+(BS34*BU34+BW34*BY34+CA34*CC34) -> 103400.96 | CZ34: =+CR34*(BS34*BU34+BW34*BY34+CA34*CC34)*0.3025 -> 2658697.2 | DA34: =+(BS34*BT34+BW34*BX34+CA34*CB34) -> 677708.59 | DB34: =+CS34*(BS34*BT34+BW34*BX34+CA34*CB34)*0.3025 -> 17015568
A35: 압구정3구역 | B35: 서울특별시 강남구 압구정동 369-1 | C35: 45992 | D35: 서울특별시 강남구공고 제 2025-2711호 | E35: 1414453 | F35: 구글링 | H35: =+I35+K35+M35+N35 -> 21108000 | I35: =+J35*CY35*0.3025 -> 2658697.2 | J35: 85 | K35: =+L35*DA35*0.3025 -> 17015568 | L35: 83 | M35: =+CP35 -> 101095.5 | N35: 1332639 | P35: =+Q35+R35 -> 5887500 | Q35: =+T35*E35*0.3025 -> 4528846.2 | R35: =+Q35*S35 -> 1358653.8 | S35: =+BI35 -> 0.3 | T35: =+BJ35 -> 10.584581 | V35: 24930400 | W35: 23069157 | X35: =+V35-W35 -> 1861243 | Z35: 15 | AA35: 13차 | AB35: 36B | AC35: 4660 | AD35: 6150 | AE35: 119 | AF35: 46160 | AH35: =+AR35*L35*0.3025 -> 2862.255 | AI35: =+J35*AR35*0.3025 -> 2931.225 | AJ35: =+(H35-P35)/V35 -> 0.61051969 | AL35: 래미안원베일리 | AM35: 서울시 서초구 반포동 1 | AN35: 6700 | AO35: =+AF35 -> 46160 | AP35: 111.79 | AQ35: =+AN35/(AP35*0.3025) -> 198.12828 | AR35: 114 | AS35: 0.2 | AT35: =+AQ35*AR35*(1+AS35)*0.3025 -> 8198.9444 | AU35: =+AD35+AZ35 -> 6167.2333 | AV35: =+AT35-AU35 -> 2031.7112 | AZ35: =+AH35-(AC35*AJ35) -> 17.233259 | BB35: =+AV35/AU35 -> 0.32943641 | BD35: 공사비 뽑아내기 | BF35: 5887500 | BG35: =+BF35/(1+BI35) -> 4528846.2 | BH35: =+BF35-BG35 -> 1358653.8 | BI35: 0.3 | BJ35: =+BG35/(E35*0.3025) -> 10.584581 | BO35: 3934 | BP35: =+BQ35-BO35 -> 600 | BQ35: 4534 | BR35: 522 | BS35: 80 | BT35: =+ROUND(BR35*BO35/BQ35,0) -> 453 | BU35: =+BR35-BT35 -> 69 | BV35: 486 | BW35: 114 | BX35: =+ROUND(BV35*BO35/BQ35,0) -> 422 | BY35: =+BV35-BX35 -> 64 | BZ35: 3526 | CA35: =+CW35 -> 193.97208 | CB35: =+ROUND(BZ35*BO35/BQ35,0) -> 3059 | CC35: =+BZ35-CB35 -> 467 | CE35: 641 | CG35: 511 | CH35: =+BS35 -> 80 | CI35: 130 | CJ35: =+BW35 -> 114 | CK35: =+BQ35+CE35+CF35 -> 5175 | CM35: 6 | CN35: 21108000 | CO35: =+N35 -> 1332639 | CP35: =+CM35*(CG35*CH35+CI35*CJ35)*0.3025 -> 101095.5 | CQ35: =+CN35-CO35-CP35 -> 19674266 | CR35: =+J35 -> 85 | CS35: =+L35 -> 83 | CT35: =+(CR35*BS35*BU35+CS35*BS35*BT35)*0.3025 -> 1051828.8 | CU35: =+(CR35*BW35*BY35+CS35*BW35*BX35)*0.3025 -> 1395470 | CV35: =+CQ35-CT35-CU35 -> 17226967 | CW35: =+CV35/(CR35*CC35*0.3025+CS35*CB35*0.3025) -> 193.97208 | CY35: =+(BS35*BU35+BW35*BY35+CA35*CC35) -> 103400.96 | CZ35: =+CR35*(BS35*BU35+BW35*BY35+CA35*CC35)*0.3025 -> 2658697.2 | DA35: =+(BS35*BT35+BW35*BX35+CA35*CB35) -> 677708.59 | DB35: =+CS35*(BS35*BT35+BW35*BX35+CA35*CB35)*0.3025 -> 17015568
A36: 압구정3구역 | B36: 서울특별시 강남구 압구정동 369-1 | C36: 45992 | D36: 서울특별시 강남구공고 제 2025-2711호 | E36: 1414453 | F36: 구글링 | H36: =+I36+K36+M36+N36 -> 21108000 | I36: =+J36*CY36*0.3025 -> 2658697.2 | J36: 85 | K36: =+L36*DA36*0.3025 -> 17015568 | L36: 83 | M36: =+CP36 -> 101095.5 | N36: 1332639 | P36: =+Q36+R36 -> 5887500 | Q36: =+T36*E36*0.3025 -> 4528846.2 | R36: =+Q36*S36 -> 1358653.8 | S36: =+BI36 -> 0.3 | T36: =+BJ36 -> 10.584581 | V36: 24930400 | W36: 23069157 | X36: =+V36-W36 -> 1861243 | Z36: 16 | AA36: 14차 | AB36: 32 | AC36: 4348 | AD36: 5850 | AE36: 96,99 | AF36: 46160 | AH36: =+AR36*L36*0.3025 -> 2862.255 | AI36: =+J36*AR36*0.3025 -> 2931.225 | AJ36: =+(H36-P36)/V36 -> 0.61051969 | AL36: 래미안원베일리 | AM36: 서울시 서초구 반포동 1 | AN36: 6700 | AO36: =+AF36 -> 46160 | AP36: 111.79 | AQ36: =+AN36/(AP36*0.3025) -> 198.12828 | AR36: 114 | AS36: 0.2 | AT36: =+AQ36*AR36*(1+AS36)*0.3025 -> 8198.9444 | AU36: =+AD36+AZ36 -> 6057.7154 | AV36: =+AT36-AU36 -> 2141.229 | AZ36: =+AH36-(AC36*AJ36) -> 207.7154 | BB36: =+AV36/AU36 -> 0.35347138 | BD36: 공사비 뽑아내기 | BF36: 5887500 | BG36: =+BF36/(1+BI36) -> 4528846.2 | BH36: =+BF36-BG36 -> 1358653.8 | BI36: 0.3 | BJ36: =+BG36/(E36*0.3025) -> 10.584581 | BO36: 3934 | BP36: =+BQ36-BO36 -> 600 | BQ36: 4534 | BR36: 522 | BS36: 80 | BT36: =+ROUND(BR36*BO36/BQ36,0) -> 453 | BU36: =+BR36-BT36 -> 69 | BV36: 486 | BW36: 114 | BX36: =+ROUND(BV36*BO36/BQ36,0) -> 422 | BY36: =+BV36-BX36 -> 64 | BZ36: 3526 | CA36: =+CW36 -> 193.97208 | CB36: =+ROUND(BZ36*BO36/BQ36,0) -> 3059 | CC36: =+BZ36-CB36 -> 467 | CE36: 641 | CG36: 511 | CH36: =+BS36 -> 80 | CI36: 130 | CJ36: =+BW36 -> 114 | CK36: =+BQ36+CE36+CF36 -> 5175 | CM36: 6 | CN36: 21108000 | CO36: =+N36 -> 1332639 | CP36: =+CM36*(CG36*CH36+CI36*CJ36)*0.3025 -> 101095.5 | CQ36: =+CN36-CO36-CP36 -> 19674266 | CR36: =+J36 -> 85 | CS36: =+L36 -> 83 | CT36: =+(CR36*BS36*BU36+CS36*BS36*BT36)*0.3025 -> 1051828.8 | CU36: =+(CR36*BW36*BY36+CS36*BW36*BX36)*0.3025 -> 1395470 | CV36: =+CQ36-CT36-CU36 -> 17226967 | CW36: =+CV36/(CR36*CC36*0.3025+CS36*CB36*0.3025) -> 193.97208 | CY36: =+(BS36*BU36+BW36*BY36+CA36*CC36) -> 103400.96 | CZ36: =+CR36*(BS36*BU36+BW36*BY36+CA36*CC36)*0.3025 -> 2658697.2 | DA36: =+(BS36*BT36+BW36*BX36+CA36*CB36) -> 677708.59 | DB36: =+CS36*(BS36*BT36+BW36*BX36+CA36*CB36)*0.3025 -> 17015568
A37: 압구정3구역 | B37: 서울특별시 강남구 압구정동 369-1 | C37: 45992 | D37: 서울특별시 강남구공고 제 2025-2711호 | E37: 1414453 | F37: 구글링 | H37: =+I37+K37+M37+N37 -> 21108000 | I37: =+J37*CY37*0.3025 -> 2658697.2 | J37: 85 | K37: =+L37*DA37*0.3025 -> 17015568 | L37: 83 | M37: =+CP37 -> 101095.5 | N37: 1332639 | P37: =+Q37+R37 -> 5887500 | Q37: =+T37*E37*0.3025 -> 4528846.2 | R37: =+Q37*S37 -> 1358653.8 | S37: =+BI37 -> 0.3 | T37: =+BJ37 -> 10.584581 | V37: 24930400 | W37: 23069157 | X37: =+V37-W37 -> 1861243 | Z37: 17 | AA37: 대림아크로빌 | AB37: 81 | AC37: 6467 | AD37: =+DJ37 -> 10852.128 | AE37: KB(X)-아크로빌기준추정 | AF37: 46160 | AH37: =+AR37*L37*0.3025 -> 2862.255 | AI37: =+J37*AR37*0.3025 -> 2931.225 | AJ37: =+(H37-P37)/V37 -> 0.61051969 | AL37: 래미안원베일리 | AM37: 서울시 서초구 반포동 1 | AN37: 6700 | AO37: =+AF37 -> 46160 | AP37: 111.79 | AQ37: =+AN37/(AP37*0.3025) -> 198.12828 | AR37: 114 | AS37: 0.2 | AT37: =+AQ37*AR37*(1+AS37)*0.3025 -> 8198.9444 | AU37: =+AD37+AZ37 -> 9766.152 | AV37: =+AT37-AU37 -> -1567.2075 | AZ37: =+AH37-(AC37*AJ37) -> -1085.9758 | BB37: =+AV37/AU37 -> -0.16047339 | BD37: 공사비 뽑아내기 | BF37: 5887500 | BG37: =+BF37/(1+BI37) -> 4528846.2 | BH37: =+BF37-BG37 -> 1358653.8 | BI37: 0.3 | BJ37: =+BG37/(E37*0.3025) -> 10.584581 | BO37: 3934 | BP37: =+BQ37-BO37 -> 600 | BQ37: 4534 | BR37: 522 | BS37: 80 | BT37: =+ROUND(BR37*BO37/BQ37,0) -> 453 | BU37: =+BR37-BT37 -> 69 | BV37: 486 | BW37: 114 | BX37: =+ROUND(BV37*BO37/BQ37,0) -> 422 | BY37: =+BV37-BX37 -> 64 | BZ37: 3526 | CA37: =+CW37 -> 193.97208 | CB37: =+ROUND(BZ37*BO37/BQ37,0) -> 3059 | CC37: =+BZ37-CB37 -> 467 | CE37: 641 | CG37: 511 | CH37: =+BS37 -> 80 | CI37: 130 | CJ37: =+BW37 -> 114 | CK37: =+BQ37+CE37+CF37 -> 5175 | CM37: 6 | CN37: 21108000 | CO37: =+N37 -> 1332639 | CP37: =+CM37*(CG37*CH37+CI37*CJ37)*0.3025 -> 101095.5 | CQ37: =+CN37-CO37-CP37 -> 19674266 | CR37: =+J37 -> 85 | CS37: =+L37 -> 83 | CT37: =+(CR37*BS37*BU37+CS37*BS37*BT37)*0.3025 -> 1051828.8 | CU37: =+(CR37*BW37*BY37+CS37*BW37*BX37)*0.3025 -> 1395470 | CV37: =+CQ37-CT37-CU37 -> 17226967 | CW37: =+CV37/(CR37*CC37*0.3025+CS37*CB37*0.3025) -> 193.97208 | CY37: =+(BS37*BU37+BW37*BY37+CA37*CC37) -> 103400.96 | CZ37: =+CR37*(BS37*BU37+BW37*BY37+CA37*CC37)*0.3025 -> 2658697.2 | DA37: =+(BS37*BT37+BW37*BX37+CA37*CB37) -> 677708.59 | DB37: =+CS37*(BS37*BT37+BW37*BX37+CA37*CB37)*0.3025 -> 17015568 | DF37: 17 | DG37: 대림아크로빌 | DH37: 75 | DI37: 6467 | DJ37: =+$DJ$38*DI37/$DI$38 -> 10852.128 | DL37: 46160
A38: 압구정3구역 | B38: 서울특별시 강남구 압구정동 369-1 | C38: 45992 | D38: 서울특별시 강남구공고 제 2025-2711호 | E38: 1414453 | F38: 구글링 | H38: =+I38+K38+M38+N38 -> 21108000 | I38: =+J38*CY38*0.3025 -> 2658697.2 | J38: 85 | K38: =+L38*DA38*0.3025 -> 17015568 | L38: 83 | M38: =+CP38 -> 101095.5 | N38: 1332639 | P38: =+Q38+R38 -> 5887500 | Q38: =+T38*E38*0.3025 -> 4528846.2 | R38: =+Q38*S38 -> 1358653.8 | S38: =+BI38 -> 0.3 | T38: =+BJ38 -> 10.584581 | V38: 24930400 | W38: 23069157 | X38: =+V38-W38 -> 1861243 | Z38: 18 | AA38: 대림아크로빌 | AB38: 85 | AC38: 7449 | AD38: 12500 | AE38: 281 | AF38: 46160 | AH38: =+AR38*L38*0.3025 -> 2862.255 | AI38: =+J38*AR38*0.3025 -> 2931.225 | AJ38: =+(H38-P38)/V38 -> 0.61051969 | AL38: 래미안원베일리 | AM38: 서울시 서초구 반포동 1 | AN38: 6700 | AO38: =+AF38 -> 46160 | AP38: 111.79 | AQ38: =+AN38/(AP38*0.3025) -> 198.12828 | AR38: 114 | AS38: 0.2 | AT38: =+AQ38*AR38*(1+AS38)*0.3025 -> 8198.9444 | AU38: =+AD38+AZ38 -> 10814.494 | AV38: =+AT38-AU38 -> -2615.5494 | AZ38: =+AH38-(AC38*AJ38) -> -1685.5061 | BB38: =+AV38/AU38 -> -0.24185592 | BD38: 공사비 뽑아내기 | BF38: 5887500 | BG38: =+BF38/(1+BI38) -> 4528846.2 | BH38: =+BF38-BG38 -> 1358653.8 | BI38: 0.3 | BJ38: =+BG38/(E38*0.3025) -> 10.584581 | BO38: 3934 | BP38: =+BQ38-BO38 -> 600 | BQ38: 4534 | BR38: 522 | BS38: 80 | BT38: =+ROUND(BR38*BO38/BQ38,0) -> 453 | BU38: =+BR38-BT38 -> 69 | BV38: 486 | BW38: 114 | BX38: =+ROUND(BV38*BO38/BQ38,0) -> 422 | BY38: =+BV38-BX38 -> 64 | BZ38: 3526 | CA38: =+CW38 -> 193.97208 | CB38: =+ROUND(BZ38*BO38/BQ38,0) -> 3059 | CC38: =+BZ38-CB38 -> 467 | CE38: 641 | CG38: 511 | CH38: =+BS38 -> 80 | CI38: 130 | CJ38: =+BW38 -> 114 | CK38: =+BQ38+CE38+CF38 -> 5175 | CM38: 6 | CN38: 21108000 | CO38: =+N38 -> 1332639 | CP38: =+CM38*(CG38*CH38+CI38*CJ38)*0.3025 -> 101095.5 | CQ38: =+CN38-CO38-CP38 -> 19674266 | CR38: =+J38 -> 85 | CS38: =+L38 -> 83 | CT38: =+(CR38*BS38*BU38+CS38*BS38*BT38)*0.3025 -> 1051828.8 | CU38: =+(CR38*BW38*BY38+CS38*BW38*BX38)*0.3025 -> 1395470 | CV38: =+CQ38-CT38-CU38 -> 17226967 | CW38: =+CV38/(CR38*CC38*0.3025+CS38*CB38*0.3025) -> 193.97208 | CY38: =+(BS38*BU38+BW38*BY38+CA38*CC38) -> 103400.96 | CZ38: =+CR38*(BS38*BU38+BW38*BY38+CA38*CC38)*0.3025 -> 2658697.2 | DA38: =+(BS38*BT38+BW38*BX38+CA38*CB38) -> 677708.59 | DB38: =+CS38*(BS38*BT38+BW38*BX38+CA38*CB38)*0.3025 -> 17015568 | DF38: 18 | DG38: 대림아크로빌 | DH38: 93 | DI38: 7449 | DJ38: 12500 | DK38: 281 | DL38: 46160 | DM38: =+DJ38/DH38 -> 134.4086
A39: 압구정3구역 | B39: 서울특별시 강남구 압구정동 369-1 | C39: 45992 | D39: 서울특별시 강남구공고 제 2025-2711호 | E39: 1414453 | F39: 구글링 | H39: =+I39+K39+M39+N39 -> 21108000 | I39: =+J39*CY39*0.3025 -> 2658697.2 | J39: 85 | K39: =+L39*DA39*0.3025 -> 17015568 | L39: 83 | M39: =+CP39 -> 101095.5 | N39: 1332639 | P39: =+Q39+R39 -> 5887500 | Q39: =+T39*E39*0.3025 -> 4528846.2 | R39: =+Q39*S39 -> 1358653.8 | S39: =+BI39 -> 0.3 | T39: =+BJ39 -> 10.584581 | V39: 24930400 | W39: 23069157 | X39: =+V39-W39 -> 1861243 | Z39: 19 | AA39: 대림빌라트 | AB39: 75 | AC39: 5499 | AD39: =+DJ39 -> 9227.7487 | AE39: KB(X)-아크로빌기준추정 | AF39: 46160 | AH39: =+AR39*L39*0.3025 -> 2862.255 | AI39: =+J39*AR39*0.3025 -> 2931.225 | AJ39: =+(H39-P39)/V39 -> 0.61051969 | AL39: 래미안원베일리 | AM39: 서울시 서초구 반포동 1 | AN39: 6700 | AO39: =+AF39 -> 46160 | AP39: 111.79 | AQ39: =+AN39/(AP39*0.3025) -> 198.12828 | AR39: 114 | AS39: 0.2 | AT39: =+AQ39*AR39*(1+AS39)*0.3025 -> 8198.9444 | AU39: =+AD39+AZ39 -> 8732.7559 | AV39: =+AT39-AU39 -> -533.81148 | AZ39: =+AH39-(AC39*AJ39) -> -494.99276 | BB39: =+AV39/AU39 -> -0.061127494 | BD39: 공사비 뽑아내기 | BF39: 5887500 | BG39: =+BF39/(1+BI39) -> 4528846.2 | BH39: =+BF39-BG39 -> 1358653.8 | BI39: 0.3 | BJ39: =+BG39/(E39*0.3025) -> 10.584581 | BO39: 3934 | BP39: =+BQ39-BO39 -> 600 | BQ39: 4534 | BR39: 522 | BS39: 80 | BT39: =+ROUND(BR39*BO39/BQ39,0) -> 453 | BU39: =+BR39-BT39 -> 69 | BV39: 486 | BW39: 114 | BX39: =+ROUND(BV39*BO39/BQ39,0) -> 422 | BY39: =+BV39-BX39 -> 64 | BZ39: 3526 | CA39: =+CW39 -> 193.97208 | CB39: =+ROUND(BZ39*BO39/BQ39,0) -> 3059 | CC39: =+BZ39-CB39 -> 467 | CE39: 641 | CG39: 511 | CH39: =+BS39 -> 80 | CI39: 130 | CJ39: =+BW39 -> 114 | CK39: =+BQ39+CE39+CF39 -> 5175 | CM39: 6 | CN39: 21108000 | CO39: =+N39 -> 1332639 | CP39: =+CM39*(CG39*CH39+CI39*CJ39)*0.3025 -> 101095.5 | CQ39: =+CN39-CO39-CP39 -> 19674266 | CR39: =+J39 -> 85 | CS39: =+L39 -> 83 | CT39: =+(CR39*BS39*BU39+CS39*BS39*BT39)*0.3025 -> 1051828.8 | CU39: =+(CR39*BW39*BY39+CS39*BW39*BX39)*0.3025 -> 1395470 | CV39: =+CQ39-CT39-CU39 -> 17226967 | CW39: =+CV39/(CR39*CC39*0.3025+CS39*CB39*0.3025) -> 193.97208 | CY39: =+(BS39*BU39+BW39*BY39+CA39*CC39) -> 103400.96 | CZ39: =+CR39*(BS39*BU39+BW39*BY39+CA39*CC39)*0.3025 -> 2658697.2 | DA39: =+(BS39*BT39+BW39*BX39+CA39*CB39) -> 677708.59 | DB39: =+CS39*(BS39*BT39+BW39*BX39+CA39*CB39)*0.3025 -> 17015568 | DF39: 19 | DG39: 대림빌라트 | DH39: 75 | DI39: 5499 | DJ39: =+$DJ$38*DI39/$DI$38 -> 9227.7487 | DL39: 46160
A40: 압구정3구역 | B40: 서울특별시 강남구 압구정동 369-1 | C40: 45992 | D40: 서울특별시 강남구공고 제 2025-2711호 | E40: 1414453 | F40: 구글링 | H40: =+I40+K40+M40+N40 -> 21108000 | I40: =+J40*CY40*0.3025 -> 2658697.2 | J40: 85 | K40: =+L40*DA40*0.3025 -> 17015568 | L40: 83 | M40: =+CP40 -> 101095.5 | N40: 1332639 | P40: =+Q40+R40 -> 5887500 | Q40: =+T40*E40*0.3025 -> 4528846.2 | R40: =+Q40*S40 -> 1358653.8 | S40: =+BI40 -> 0.3 | T40: =+BJ40 -> 10.584581 | V40: 24930400 | W40: 23069157 | X40: =+V40-W40 -> 1861243 | Z40: 20 | AA40: 대림빌라트 | AB40: 93 | AC40: 6602 | AD40: =+DJ40 -> 11078.668 | AE40: KB(X)-아크로빌기준추정 | AF40: 46160 | AH40: =+AR40*L40*0.3025 -> 2862.255 | AI40: =+J40*AR40*0.3025 -> 2931.225 | AJ40: =+(H40-P40)/V40 -> 0.61051969 | AL40: 래미안원베일리 | AM40: 서울시 서초구 반포동 1 | AN40: 6700 | AO40: =+AF40 -> 46160 | AP40: 111.79 | AQ40: =+AN40/(AP40*0.3025) -> 198.12828 | AR40: 114 | AS40: 0.2 | AT40: =+AQ40*AR40*(1+AS40)*0.3025 -> 8198.9444 | AU40: =+AD40+AZ40 -> 9910.2723 | AV40: =+AT40-AU40 -> -1711.3279 | AZ40: =+AH40-(AC40*AJ40) -> -1168.396 | BB40: =+AV40/AU40 -> -0.17268222 | BD40: 공사비 뽑아내기 | BF40: 5887500 | BG40: =+BF40/(1+BI40) -> 4528846.2 | BH40: =+BF40-BG40 -> 1358653.8 | BI40: 0.3 | BJ40: =+BG40/(E40*0.3025) -> 10.584581 | BO40: 3934 | BP40: =+BQ40-BO40 -> 600 | BQ40: 4534 | BR40: 522 | BS40: 80 | BT40: =+ROUND(BR40*BO40/BQ40,0) -> 453 | BU40: =+BR40-BT40 -> 69 | BV40: 486 | BW40: 114 | BX40: =+ROUND(BV40*BO40/BQ40,0) -> 422 | BY40: =+BV40-BX40 -> 64 | BZ40: 3526 | CA40: =+CW40 -> 193.97208 | CB40: =+ROUND(BZ40*BO40/BQ40,0) -> 3059 | CC40: =+BZ40-CB40 -> 467 | CE40: 641 | CG40: 511 | CH40: =+BS40 -> 80 | CI40: 130 | CJ40: =+BW40 -> 114 | CK40: =+BQ40+CE40+CF40 -> 5175 | CM40: 6 | CN40: 21108000 | CO40: =+N40 -> 1332639 | CP40: =+CM40*(CG40*CH40+CI40*CJ40)*0.3025 -> 101095.5 | CQ40: =+CN40-CO40-CP40 -> 19674266 | CR40: =+J40 -> 85 | CS40: =+L40 -> 83 | CT40: =+(CR40*BS40*BU40+CS40*BS40*BT40)*0.3025 -> 1051828.8 | CU40: =+(CR40*BW40*BY40+CS40*BW40*BX40)*0.3025 -> 1395470 | CV40: =+CQ40-CT40-CU40 -> 17226967 | CW40: =+CV40/(CR40*CC40*0.3025+CS40*CB40*0.3025) -> 193.97208 | CY40: =+(BS40*BU40+BW40*BY40+CA40*CC40) -> 103400.96 | CZ40: =+CR40*(BS40*BU40+BW40*BY40+CA40*CC40)*0.3025 -> 2658697.2 | DA40: =+(BS40*BT40+BW40*BX40+CA40*CB40) -> 677708.59 | DB40: =+CS40*(BS40*BT40+BW40*BX40+CA40*CB40)*0.3025 -> 17015568 | DF40: 20 | DG40: 대림빌라트 | DH40: 93 | DI40: 6602 | DJ40: =+$DJ$38*DI40/$DI$38 -> 11078.668 | DL40: 46160
A41: 압구정3구역 | B41: 서울특별시 강남구 압구정동 369-1 | C41: 45992 | D41: 서울특별시 강남구공고 제 2025-2711호 | E41: 1414453 | F41: 구글링 | H41: =+I41+K41+M41+N41 -> 21108000 | I41: =+J41*CY41*0.3025 -> 2658697.2 | J41: 85 | K41: =+L41*DA41*0.3025 -> 17015568 | L41: 83 | M41: =+CP41 -> 101095.5 | N41: 1332639 | P41: =+Q41+R41 -> 5887500 | Q41: =+T41*E41*0.3025 -> 4528846.2 | R41: =+Q41*S41 -> 1358653.8 | S41: =+BI41 -> 0.3 | T41: =+BJ41 -> 10.584581 | V41: 24930400 | W41: 23069157 | X41: =+V41-W41 -> 1861243 | Z41: 21 | AA41: 현대빌라트 | AB41: 73 | AC41: 5490 | AD41: =+DJ41 -> 9212.646 | AE41: KB(X)-아크로빌기준추정 | AF41: 46160 | AH41: =+AR41*L41*0.3025 -> 2862.255 | AI41: =+J41*AR41*0.3025 -> 2931.225 | AJ41: =+(H41-P41)/V41 -> 0.61051969 | AL41: 래미안원베일리 | AM41: 서울시 서초구 반포동 1 | AN41: 6700 | AO41: =+AF41 -> 46160 | AP41: 111.79 | AQ41: =+AN41/(AP41*0.3025) -> 198.12828 | AR41: 114 | AS41: 0.2 | AT41: =+AQ41*AR41*(1+AS41)*0.3025 -> 8198.9444 | AU41: =+AD41+AZ41 -> 8723.1479 | AV41: =+AT41-AU41 -> -524.20346 | AZ41: =+AH41-(AC41*AJ41) -> -489.49808 | BB41: =+AV41/AU41 -> -0.060093382 | BD41: 공사비 뽑아내기 | BF41: 5887500 | BG41: =+BF41/(1+BI41) -> 4528846.2 | BH41: =+BF41-BG41 -> 1358653.8 | BI41: 0.3 | BJ41: =+BG41/(E41*0.3025) -> 10.584581 | BO41: 3934 | BP41: =+BQ41-BO41 -> 600 | BQ41: 4534 | BR41: 522 | BS41: 80 | BT41: =+ROUND(BR41*BO41/BQ41,0) -> 453 | BU41: =+BR41-BT41 -> 69 | BV41: 486 | BW41: 114 | BX41: =+ROUND(BV41*BO41/BQ41,0) -> 422 | BY41: =+BV41-BX41 -> 64 | BZ41: 3526 | CA41: =+CW41 -> 193.97208 | CB41: =+ROUND(BZ41*BO41/BQ41,0) -> 3059 | CC41: =+BZ41-CB41 -> 467 | CE41: 641 | CG41: 511 | CH41: =+BS41 -> 80 | CI41: 130 | CJ41: =+BW41 -> 114 | CK41: =+BQ41+CE41+CF41 -> 5175 | CM41: 6 | CN41: 21108000 | CO41: =+N41 -> 1332639 | CP41: =+CM41*(CG41*CH41+CI41*CJ41)*0.3025 -> 101095.5 | CQ41: =+CN41-CO41-CP41 -> 19674266 | CR41: =+J41 -> 85 | CS41: =+L41 -> 83 | CT41: =+(CR41*BS41*BU41+CS41*BS41*BT41)*0.3025 -> 1051828.8 | CU41: =+(CR41*BW41*BY41+CS41*BW41*BX41)*0.3025 -> 1395470 | CV41: =+CQ41-CT41-CU41 -> 17226967 | CW41: =+CV41/(CR41*CC41*0.3025+CS41*CB41*0.3025) -> 193.97208 | CY41: =+(BS41*BU41+BW41*BY41+CA41*CC41) -> 103400.96 | CZ41: =+CR41*(BS41*BU41+BW41*BY41+CA41*CC41)*0.3025 -> 2658697.2 | DA41: =+(BS41*BT41+BW41*BX41+CA41*CB41) -> 677708.59 | DB41: =+CS41*(BS41*BT41+BW41*BX41+CA41*CB41)*0.3025 -> 17015568 | DF41: 21 | DG41: 현대빌라트 | DH41: 73 | DI41: 5490 | DJ41: =+$DJ$38*DI41/$DI$38 -> 9212.646 | DL41: 46160
...

Sheet 최초
G1: 건축계획 | S1: 슬라이더 | W1: 종후-조합원분양물량 | AX1: 슬라이더 | AZ1: 종후-일반분양물량 | BI1: 슬라이더 | BK1: 종후-임대물량 | BY1: 종후-주택 외 | CB1: 종전 | CG1: 매주업데이트 | CM1: 매주업데이트 | CS1: 매주업데이트 | CY1: 매주업데이트 | DE1: 매주업데이트 | DK1: 매주업데이트 | DQ1: 매주업데이트 | DW1: 매주업데이트 | EC1: 매주업데이트 | EI1: 매주업데이트 | EO1: 매주업데이트 | EU1: 매주업데이트 | FA1: 매주업데이트 | FG1: 매주업데이트 | FM1: 매주업데이트 | FS1: 매주업데이트 | FY1: 매주업데이트 | GE1: 매주업데이트 | GK1: 매주업데이트 | GQ1: 매주업데이트 | GW1: 매주업데이트 | HC1: 매주업데이트 | HJ1: 마진 계산용 참고단지 자료 | HL1: 매주업데이트 | HS1: 분담금 시뮬레이션 | JN1: 마진 시뮬레이션 | ME1: 랭킹 기준
